2023-11-19 20:55:52,243 -  nornir.core -     INFO -        run() - Running task 'netmiko_send_command' with args {'command_string': 'Show ip int br', 'use_textfsm': True} on 2 hosts
2023-11-19 20:59:01,097 -  nornir.core -     INFO -        run() - Running task 'netmiko_send_command' with args {'command_string': 'Show ip int br', 'use_textfsm': True} on 2 hosts
2023-11-19 20:59:46,967 -  nornir.core -     INFO -        run() - Running task 'netmiko_send_command' with args {'command_string': 'Show ip int br', 'use_textfsm': True} on 2 hosts
2023-11-19 21:00:08,183 -  nornir.core -     INFO -        run() - Running task 'netmiko_send_command' with args {'command_string': 'Show ip int br', 'use_textfsm': True} on 2 hosts
2023-11-19 21:03:04,663 -  nornir.core -     INFO -        run() - Running task 'netmiko_send_command' with args {'command_string': 'Show ip int br', 'use_textfsm': True} on 2 hosts
2023-11-19 21:05:58,363 -  nornir.core -     INFO -        run() - Running task 'netmiko_send_command' with args {'command_string': 'Show ip int br', 'use_textfsm': True} on 2 hosts
2023-11-19 21:06:08,586 -  nornir.core -     INFO -        run() - Running task 'netmiko_send_command' with args {'command_string': 'Show ip int br', 'use_textfsm': True} on 2 hosts
2023-11-19 21:08:25,306 -  nornir.core -     INFO -        run() - Running task 'netmiko_send_command' with args {'command_string': 'Show ip int br', 'use_textfsm': True} on 2 hosts
2023-11-19 21:09:44,808 -  nornir.core -     INFO -        run() - Running task 'netmiko_send_command' with args {'command_string': 'Show ip int br', 'use_textfsm': True} on 2 hosts
2023-11-21 13:13:45,684 -  nornir.core -     INFO -        run() - Running task 'netmiko_send_command' with args {'command_string': 'Show ip int br', 'use_textfsm': True} on 10 hosts
2023-11-21 17:06:51,916 -  nornir.core -     INFO -        run() - Running task 'netmiko_send_command' with args {'command_string': 'Show ip int br', 'use_textfsm': True} on 10 hosts
2023-11-21 17:07:01,960 - nornir.core.task -    ERROR -      start() - Host 'R5': task 'netmiko_send_command' failed with traceback:
Traceback (most recent call last):
  File "C:\Users\Jithin Jose\OneDrive - NAIT\BAITS\NETW3100\NETW3100\Lib\site-packages\netmiko\base_connection.py", line 1046, in establish_connection
    self.remote_conn_pre.connect(**ssh_connect_params)
  File "C:\Users\Jithin Jose\OneDrive - NAIT\BAITS\NETW3100\NETW3100\Lib\site-packages\paramiko\client.py", line 386, in connect
    sock.connect(addr)
TimeoutError: timed out

During handling of the above exception, another exception occurred:

Traceback (most recent call last):
  File "C:\Users\Jithin Jose\OneDrive - NAIT\BAITS\NETW3100\NETW3100\Lib\site-packages\nornir\core\task.py", line 99, in start
    r = self.task(self, **self.params)
        ^^^^^^^^^^^^^^^^^^^^^^^^^^^^^^
  File "C:\Users\Jithin Jose\OneDrive - NAIT\BAITS\NETW3100\NETW3100\Lib\site-packages\nornir_netmiko\tasks\netmiko_send_command.py", line 26, in netmiko_send_command
    net_connect = task.host.get_connection(CONNECTION_NAME, task.nornir.config)
                  ^^^^^^^^^^^^^^^^^^^^^^^^^^^^^^^^^^^^^^^^^^^^^^^^^^^^^^^^^^^^^
  File "C:\Users\Jithin Jose\OneDrive - NAIT\BAITS\NETW3100\NETW3100\Lib\site-packages\nornir\core\inventory.py", line 494, in get_connection
    self.open_connection(
  File "C:\Users\Jithin Jose\OneDrive - NAIT\BAITS\NETW3100\NETW3100\Lib\site-packages\nornir\core\inventory.py", line 546, in open_connection
    conn_obj.open(
  File "C:\Users\Jithin Jose\OneDrive - NAIT\BAITS\NETW3100\NETW3100\Lib\site-packages\nornir_netmiko\connections\netmiko.py", line 59, in open
    connection = ConnectHandler(**parameters)
                 ^^^^^^^^^^^^^^^^^^^^^^^^^^^^
  File "C:\Users\Jithin Jose\OneDrive - NAIT\BAITS\NETW3100\NETW3100\Lib\site-packages\netmiko\ssh_dispatcher.py", line 365, in ConnectHandler
    return ConnectionClass(*args, **kwargs)
           ^^^^^^^^^^^^^^^^^^^^^^^^^^^^^^^^
  File "C:\Users\Jithin Jose\OneDrive - NAIT\BAITS\NETW3100\NETW3100\Lib\site-packages\netmiko\base_connection.py", line 439, in __init__
    self._open()
  File "C:\Users\Jithin Jose\OneDrive - NAIT\BAITS\NETW3100\NETW3100\Lib\site-packages\netmiko\base_connection.py", line 444, in _open
    self.establish_connection()
  File "C:\Users\Jithin Jose\OneDrive - NAIT\BAITS\NETW3100\NETW3100\Lib\site-packages\netmiko\base_connection.py", line 1068, in establish_connection
    raise NetmikoTimeoutException(msg)
netmiko.exceptions.NetmikoTimeoutException: TCP connection to device failed.

Common causes of this problem are:
1. Incorrect hostname or IP address.
2. Wrong TCP port.
3. Intermediate firewall blocking access.

Device settings: cisco_ios 192.168.3.5:22



2023-11-21 17:07:01,960 - nornir.core.task -    ERROR -      start() - Host 'R4': task 'netmiko_send_command' failed with traceback:
Traceback (most recent call last):
  File "C:\Users\Jithin Jose\OneDrive - NAIT\BAITS\NETW3100\NETW3100\Lib\site-packages\netmiko\base_connection.py", line 1046, in establish_connection
    self.remote_conn_pre.connect(**ssh_connect_params)
  File "C:\Users\Jithin Jose\OneDrive - NAIT\BAITS\NETW3100\NETW3100\Lib\site-packages\paramiko\client.py", line 386, in connect
    sock.connect(addr)
TimeoutError: timed out

During handling of the above exception, another exception occurred:

Traceback (most recent call last):
  File "C:\Users\Jithin Jose\OneDrive - NAIT\BAITS\NETW3100\NETW3100\Lib\site-packages\nornir\core\task.py", line 99, in start
    r = self.task(self, **self.params)
        ^^^^^^^^^^^^^^^^^^^^^^^^^^^^^^
  File "C:\Users\Jithin Jose\OneDrive - NAIT\BAITS\NETW3100\NETW3100\Lib\site-packages\nornir_netmiko\tasks\netmiko_send_command.py", line 26, in netmiko_send_command
    net_connect = task.host.get_connection(CONNECTION_NAME, task.nornir.config)
                  ^^^^^^^^^^^^^^^^^^^^^^^^^^^^^^^^^^^^^^^^^^^^^^^^^^^^^^^^^^^^^
  File "C:\Users\Jithin Jose\OneDrive - NAIT\BAITS\NETW3100\NETW3100\Lib\site-packages\nornir\core\inventory.py", line 494, in get_connection
    self.open_connection(
  File "C:\Users\Jithin Jose\OneDrive - NAIT\BAITS\NETW3100\NETW3100\Lib\site-packages\nornir\core\inventory.py", line 546, in open_connection
    conn_obj.open(
  File "C:\Users\Jithin Jose\OneDrive - NAIT\BAITS\NETW3100\NETW3100\Lib\site-packages\nornir_netmiko\connections\netmiko.py", line 59, in open
    connection = ConnectHandler(**parameters)
                 ^^^^^^^^^^^^^^^^^^^^^^^^^^^^
  File "C:\Users\Jithin Jose\OneDrive - NAIT\BAITS\NETW3100\NETW3100\Lib\site-packages\netmiko\ssh_dispatcher.py", line 365, in ConnectHandler
    return ConnectionClass(*args, **kwargs)
           ^^^^^^^^^^^^^^^^^^^^^^^^^^^^^^^^
  File "C:\Users\Jithin Jose\OneDrive - NAIT\BAITS\NETW3100\NETW3100\Lib\site-packages\netmiko\base_connection.py", line 439, in __init__
    self._open()
  File "C:\Users\Jithin Jose\OneDrive - NAIT\BAITS\NETW3100\NETW3100\Lib\site-packages\netmiko\base_connection.py", line 444, in _open
    self.establish_connection()
  File "C:\Users\Jithin Jose\OneDrive - NAIT\BAITS\NETW3100\NETW3100\Lib\site-packages\netmiko\base_connection.py", line 1068, in establish_connection
    raise NetmikoTimeoutException(msg)
netmiko.exceptions.NetmikoTimeoutException: TCP connection to device failed.

Common causes of this problem are:
1. Incorrect hostname or IP address.
2. Wrong TCP port.
3. Intermediate firewall blocking access.

Device settings: cisco_ios 192.168.3.4:22



2023-11-21 17:07:01,960 - nornir.core.task -    ERROR -      start() - Host 'SW2': task 'netmiko_send_command' failed with traceback:
Traceback (most recent call last):
  File "C:\Users\Jithin Jose\OneDrive - NAIT\BAITS\NETW3100\NETW3100\Lib\site-packages\netmiko\base_connection.py", line 1046, in establish_connection
    self.remote_conn_pre.connect(**ssh_connect_params)
  File "C:\Users\Jithin Jose\OneDrive - NAIT\BAITS\NETW3100\NETW3100\Lib\site-packages\paramiko\client.py", line 386, in connect
    sock.connect(addr)
TimeoutError: timed out

During handling of the above exception, another exception occurred:

Traceback (most recent call last):
  File "C:\Users\Jithin Jose\OneDrive - NAIT\BAITS\NETW3100\NETW3100\Lib\site-packages\nornir\core\task.py", line 99, in start
    r = self.task(self, **self.params)
        ^^^^^^^^^^^^^^^^^^^^^^^^^^^^^^
  File "C:\Users\Jithin Jose\OneDrive - NAIT\BAITS\NETW3100\NETW3100\Lib\site-packages\nornir_netmiko\tasks\netmiko_send_command.py", line 26, in netmiko_send_command
    net_connect = task.host.get_connection(CONNECTION_NAME, task.nornir.config)
                  ^^^^^^^^^^^^^^^^^^^^^^^^^^^^^^^^^^^^^^^^^^^^^^^^^^^^^^^^^^^^^
  File "C:\Users\Jithin Jose\OneDrive - NAIT\BAITS\NETW3100\NETW3100\Lib\site-packages\nornir\core\inventory.py", line 494, in get_connection
    self.open_connection(
  File "C:\Users\Jithin Jose\OneDrive - NAIT\BAITS\NETW3100\NETW3100\Lib\site-packages\nornir\core\inventory.py", line 546, in open_connection
    conn_obj.open(
  File "C:\Users\Jithin Jose\OneDrive - NAIT\BAITS\NETW3100\NETW3100\Lib\site-packages\nornir_netmiko\connections\netmiko.py", line 59, in open
    connection = ConnectHandler(**parameters)
                 ^^^^^^^^^^^^^^^^^^^^^^^^^^^^
  File "C:\Users\Jithin Jose\OneDrive - NAIT\BAITS\NETW3100\NETW3100\Lib\site-packages\netmiko\ssh_dispatcher.py", line 365, in ConnectHandler
    return ConnectionClass(*args, **kwargs)
           ^^^^^^^^^^^^^^^^^^^^^^^^^^^^^^^^
  File "C:\Users\Jithin Jose\OneDrive - NAIT\BAITS\NETW3100\NETW3100\Lib\site-packages\netmiko\base_connection.py", line 439, in __init__
    self._open()
  File "C:\Users\Jithin Jose\OneDrive - NAIT\BAITS\NETW3100\NETW3100\Lib\site-packages\netmiko\base_connection.py", line 444, in _open
    self.establish_connection()
  File "C:\Users\Jithin Jose\OneDrive - NAIT\BAITS\NETW3100\NETW3100\Lib\site-packages\netmiko\base_connection.py", line 1068, in establish_connection
    raise NetmikoTimeoutException(msg)
netmiko.exceptions.NetmikoTimeoutException: TCP connection to device failed.

Common causes of this problem are:
1. Incorrect hostname or IP address.
2. Wrong TCP port.
3. Intermediate firewall blocking access.

Device settings: cisco_ios 192.168.3.12:22



2023-11-21 17:07:01,960 - nornir.core.task -    ERROR -      start() - Host 'R6': task 'netmiko_send_command' failed with traceback:
Traceback (most recent call last):
  File "C:\Users\Jithin Jose\OneDrive - NAIT\BAITS\NETW3100\NETW3100\Lib\site-packages\netmiko\base_connection.py", line 1046, in establish_connection
    self.remote_conn_pre.connect(**ssh_connect_params)
  File "C:\Users\Jithin Jose\OneDrive - NAIT\BAITS\NETW3100\NETW3100\Lib\site-packages\paramiko\client.py", line 386, in connect
    sock.connect(addr)
TimeoutError: timed out

During handling of the above exception, another exception occurred:

Traceback (most recent call last):
  File "C:\Users\Jithin Jose\OneDrive - NAIT\BAITS\NETW3100\NETW3100\Lib\site-packages\nornir\core\task.py", line 99, in start
    r = self.task(self, **self.params)
        ^^^^^^^^^^^^^^^^^^^^^^^^^^^^^^
  File "C:\Users\Jithin Jose\OneDrive - NAIT\BAITS\NETW3100\NETW3100\Lib\site-packages\nornir_netmiko\tasks\netmiko_send_command.py", line 26, in netmiko_send_command
    net_connect = task.host.get_connection(CONNECTION_NAME, task.nornir.config)
                  ^^^^^^^^^^^^^^^^^^^^^^^^^^^^^^^^^^^^^^^^^^^^^^^^^^^^^^^^^^^^^
  File "C:\Users\Jithin Jose\OneDrive - NAIT\BAITS\NETW3100\NETW3100\Lib\site-packages\nornir\core\inventory.py", line 494, in get_connection
    self.open_connection(
  File "C:\Users\Jithin Jose\OneDrive - NAIT\BAITS\NETW3100\NETW3100\Lib\site-packages\nornir\core\inventory.py", line 546, in open_connection
    conn_obj.open(
  File "C:\Users\Jithin Jose\OneDrive - NAIT\BAITS\NETW3100\NETW3100\Lib\site-packages\nornir_netmiko\connections\netmiko.py", line 59, in open
    connection = ConnectHandler(**parameters)
                 ^^^^^^^^^^^^^^^^^^^^^^^^^^^^
  File "C:\Users\Jithin Jose\OneDrive - NAIT\BAITS\NETW3100\NETW3100\Lib\site-packages\netmiko\ssh_dispatcher.py", line 365, in ConnectHandler
    return ConnectionClass(*args, **kwargs)
           ^^^^^^^^^^^^^^^^^^^^^^^^^^^^^^^^
  File "C:\Users\Jithin Jose\OneDrive - NAIT\BAITS\NETW3100\NETW3100\Lib\site-packages\netmiko\base_connection.py", line 439, in __init__
    self._open()
  File "C:\Users\Jithin Jose\OneDrive - NAIT\BAITS\NETW3100\NETW3100\Lib\site-packages\netmiko\base_connection.py", line 444, in _open
    self.establish_connection()
  File "C:\Users\Jithin Jose\OneDrive - NAIT\BAITS\NETW3100\NETW3100\Lib\site-packages\netmiko\base_connection.py", line 1068, in establish_connection
    raise NetmikoTimeoutException(msg)
netmiko.exceptions.NetmikoTimeoutException: TCP connection to device failed.

Common causes of this problem are:
1. Incorrect hostname or IP address.
2. Wrong TCP port.
3. Intermediate firewall blocking access.

Device settings: cisco_ios 192.168.3.6:22



2023-11-21 17:15:33,441 -  nornir.core -     INFO -        run() - Running task 'netmiko_send_command' with args {'command_string': 'Show ip int br', 'use_textfsm': True} on 10 hosts
2023-11-21 17:15:43,585 - nornir.core.task -    ERROR -      start() - Host 'SW2': task 'netmiko_send_command' failed with traceback:
Traceback (most recent call last):
  File "C:\Users\Jithin Jose\OneDrive - NAIT\BAITS\NETW3100\NETW3100\Lib\site-packages\netmiko\base_connection.py", line 1046, in establish_connection
    self.remote_conn_pre.connect(**ssh_connect_params)
  File "C:\Users\Jithin Jose\OneDrive - NAIT\BAITS\NETW3100\NETW3100\Lib\site-packages\paramiko\client.py", line 386, in connect
    sock.connect(addr)
TimeoutError: timed out

During handling of the above exception, another exception occurred:

Traceback (most recent call last):
  File "C:\Users\Jithin Jose\OneDrive - NAIT\BAITS\NETW3100\NETW3100\Lib\site-packages\nornir\core\task.py", line 99, in start
    r = self.task(self, **self.params)
        ^^^^^^^^^^^^^^^^^^^^^^^^^^^^^^
  File "C:\Users\Jithin Jose\OneDrive - NAIT\BAITS\NETW3100\NETW3100\Lib\site-packages\nornir_netmiko\tasks\netmiko_send_command.py", line 26, in netmiko_send_command
    net_connect = task.host.get_connection(CONNECTION_NAME, task.nornir.config)
                  ^^^^^^^^^^^^^^^^^^^^^^^^^^^^^^^^^^^^^^^^^^^^^^^^^^^^^^^^^^^^^
  File "C:\Users\Jithin Jose\OneDrive - NAIT\BAITS\NETW3100\NETW3100\Lib\site-packages\nornir\core\inventory.py", line 494, in get_connection
    self.open_connection(
  File "C:\Users\Jithin Jose\OneDrive - NAIT\BAITS\NETW3100\NETW3100\Lib\site-packages\nornir\core\inventory.py", line 546, in open_connection
    conn_obj.open(
  File "C:\Users\Jithin Jose\OneDrive - NAIT\BAITS\NETW3100\NETW3100\Lib\site-packages\nornir_netmiko\connections\netmiko.py", line 59, in open
    connection = ConnectHandler(**parameters)
                 ^^^^^^^^^^^^^^^^^^^^^^^^^^^^
  File "C:\Users\Jithin Jose\OneDrive - NAIT\BAITS\NETW3100\NETW3100\Lib\site-packages\netmiko\ssh_dispatcher.py", line 365, in ConnectHandler
    return ConnectionClass(*args, **kwargs)
           ^^^^^^^^^^^^^^^^^^^^^^^^^^^^^^^^
  File "C:\Users\Jithin Jose\OneDrive - NAIT\BAITS\NETW3100\NETW3100\Lib\site-packages\netmiko\base_connection.py", line 439, in __init__
    self._open()
  File "C:\Users\Jithin Jose\OneDrive - NAIT\BAITS\NETW3100\NETW3100\Lib\site-packages\netmiko\base_connection.py", line 444, in _open
    self.establish_connection()
  File "C:\Users\Jithin Jose\OneDrive - NAIT\BAITS\NETW3100\NETW3100\Lib\site-packages\netmiko\base_connection.py", line 1068, in establish_connection
    raise NetmikoTimeoutException(msg)
netmiko.exceptions.NetmikoTimeoutException: TCP connection to device failed.

Common causes of this problem are:
1. Incorrect hostname or IP address.
2. Wrong TCP port.
3. Intermediate firewall blocking access.

Device settings: cisco_ios 192.168.3.12:22



2023-11-21 17:15:43,585 - nornir.core.task -    ERROR -      start() - Host 'R6': task 'netmiko_send_command' failed with traceback:
Traceback (most recent call last):
  File "C:\Users\Jithin Jose\OneDrive - NAIT\BAITS\NETW3100\NETW3100\Lib\site-packages\netmiko\base_connection.py", line 1046, in establish_connection
    self.remote_conn_pre.connect(**ssh_connect_params)
  File "C:\Users\Jithin Jose\OneDrive - NAIT\BAITS\NETW3100\NETW3100\Lib\site-packages\paramiko\client.py", line 386, in connect
    sock.connect(addr)
TimeoutError: timed out

During handling of the above exception, another exception occurred:

Traceback (most recent call last):
  File "C:\Users\Jithin Jose\OneDrive - NAIT\BAITS\NETW3100\NETW3100\Lib\site-packages\nornir\core\task.py", line 99, in start
    r = self.task(self, **self.params)
        ^^^^^^^^^^^^^^^^^^^^^^^^^^^^^^
  File "C:\Users\Jithin Jose\OneDrive - NAIT\BAITS\NETW3100\NETW3100\Lib\site-packages\nornir_netmiko\tasks\netmiko_send_command.py", line 26, in netmiko_send_command
    net_connect = task.host.get_connection(CONNECTION_NAME, task.nornir.config)
                  ^^^^^^^^^^^^^^^^^^^^^^^^^^^^^^^^^^^^^^^^^^^^^^^^^^^^^^^^^^^^^
  File "C:\Users\Jithin Jose\OneDrive - NAIT\BAITS\NETW3100\NETW3100\Lib\site-packages\nornir\core\inventory.py", line 494, in get_connection
    self.open_connection(
  File "C:\Users\Jithin Jose\OneDrive - NAIT\BAITS\NETW3100\NETW3100\Lib\site-packages\nornir\core\inventory.py", line 546, in open_connection
    conn_obj.open(
  File "C:\Users\Jithin Jose\OneDrive - NAIT\BAITS\NETW3100\NETW3100\Lib\site-packages\nornir_netmiko\connections\netmiko.py", line 59, in open
    connection = ConnectHandler(**parameters)
                 ^^^^^^^^^^^^^^^^^^^^^^^^^^^^
  File "C:\Users\Jithin Jose\OneDrive - NAIT\BAITS\NETW3100\NETW3100\Lib\site-packages\netmiko\ssh_dispatcher.py", line 365, in ConnectHandler
    return ConnectionClass(*args, **kwargs)
           ^^^^^^^^^^^^^^^^^^^^^^^^^^^^^^^^
  File "C:\Users\Jithin Jose\OneDrive - NAIT\BAITS\NETW3100\NETW3100\Lib\site-packages\netmiko\base_connection.py", line 439, in __init__
    self._open()
  File "C:\Users\Jithin Jose\OneDrive - NAIT\BAITS\NETW3100\NETW3100\Lib\site-packages\netmiko\base_connection.py", line 444, in _open
    self.establish_connection()
  File "C:\Users\Jithin Jose\OneDrive - NAIT\BAITS\NETW3100\NETW3100\Lib\site-packages\netmiko\base_connection.py", line 1068, in establish_connection
    raise NetmikoTimeoutException(msg)
netmiko.exceptions.NetmikoTimeoutException: TCP connection to device failed.

Common causes of this problem are:
1. Incorrect hostname or IP address.
2. Wrong TCP port.
3. Intermediate firewall blocking access.

Device settings: cisco_ios 192.168.3.6:22



2023-11-21 17:15:43,585 - nornir.core.task -    ERROR -      start() - Host 'R5': task 'netmiko_send_command' failed with traceback:
Traceback (most recent call last):
  File "C:\Users\Jithin Jose\OneDrive - NAIT\BAITS\NETW3100\NETW3100\Lib\site-packages\netmiko\base_connection.py", line 1046, in establish_connection
    self.remote_conn_pre.connect(**ssh_connect_params)
  File "C:\Users\Jithin Jose\OneDrive - NAIT\BAITS\NETW3100\NETW3100\Lib\site-packages\paramiko\client.py", line 386, in connect
    sock.connect(addr)
TimeoutError: timed out

During handling of the above exception, another exception occurred:

Traceback (most recent call last):
  File "C:\Users\Jithin Jose\OneDrive - NAIT\BAITS\NETW3100\NETW3100\Lib\site-packages\nornir\core\task.py", line 99, in start
    r = self.task(self, **self.params)
        ^^^^^^^^^^^^^^^^^^^^^^^^^^^^^^
  File "C:\Users\Jithin Jose\OneDrive - NAIT\BAITS\NETW3100\NETW3100\Lib\site-packages\nornir_netmiko\tasks\netmiko_send_command.py", line 26, in netmiko_send_command
    net_connect = task.host.get_connection(CONNECTION_NAME, task.nornir.config)
                  ^^^^^^^^^^^^^^^^^^^^^^^^^^^^^^^^^^^^^^^^^^^^^^^^^^^^^^^^^^^^^
  File "C:\Users\Jithin Jose\OneDrive - NAIT\BAITS\NETW3100\NETW3100\Lib\site-packages\nornir\core\inventory.py", line 494, in get_connection
    self.open_connection(
  File "C:\Users\Jithin Jose\OneDrive - NAIT\BAITS\NETW3100\NETW3100\Lib\site-packages\nornir\core\inventory.py", line 546, in open_connection
    conn_obj.open(
  File "C:\Users\Jithin Jose\OneDrive - NAIT\BAITS\NETW3100\NETW3100\Lib\site-packages\nornir_netmiko\connections\netmiko.py", line 59, in open
    connection = ConnectHandler(**parameters)
                 ^^^^^^^^^^^^^^^^^^^^^^^^^^^^
  File "C:\Users\Jithin Jose\OneDrive - NAIT\BAITS\NETW3100\NETW3100\Lib\site-packages\netmiko\ssh_dispatcher.py", line 365, in ConnectHandler
    return ConnectionClass(*args, **kwargs)
           ^^^^^^^^^^^^^^^^^^^^^^^^^^^^^^^^
  File "C:\Users\Jithin Jose\OneDrive - NAIT\BAITS\NETW3100\NETW3100\Lib\site-packages\netmiko\base_connection.py", line 439, in __init__
    self._open()
  File "C:\Users\Jithin Jose\OneDrive - NAIT\BAITS\NETW3100\NETW3100\Lib\site-packages\netmiko\base_connection.py", line 444, in _open
    self.establish_connection()
  File "C:\Users\Jithin Jose\OneDrive - NAIT\BAITS\NETW3100\NETW3100\Lib\site-packages\netmiko\base_connection.py", line 1068, in establish_connection
    raise NetmikoTimeoutException(msg)
netmiko.exceptions.NetmikoTimeoutException: TCP connection to device failed.

Common causes of this problem are:
1. Incorrect hostname or IP address.
2. Wrong TCP port.
3. Intermediate firewall blocking access.

Device settings: cisco_ios 192.168.3.5:22



2023-11-21 17:15:43,585 - nornir.core.task -    ERROR -      start() - Host 'R4': task 'netmiko_send_command' failed with traceback:
Traceback (most recent call last):
  File "C:\Users\Jithin Jose\OneDrive - NAIT\BAITS\NETW3100\NETW3100\Lib\site-packages\netmiko\base_connection.py", line 1046, in establish_connection
    self.remote_conn_pre.connect(**ssh_connect_params)
  File "C:\Users\Jithin Jose\OneDrive - NAIT\BAITS\NETW3100\NETW3100\Lib\site-packages\paramiko\client.py", line 386, in connect
    sock.connect(addr)
TimeoutError: timed out

During handling of the above exception, another exception occurred:

Traceback (most recent call last):
  File "C:\Users\Jithin Jose\OneDrive - NAIT\BAITS\NETW3100\NETW3100\Lib\site-packages\nornir\core\task.py", line 99, in start
    r = self.task(self, **self.params)
        ^^^^^^^^^^^^^^^^^^^^^^^^^^^^^^
  File "C:\Users\Jithin Jose\OneDrive - NAIT\BAITS\NETW3100\NETW3100\Lib\site-packages\nornir_netmiko\tasks\netmiko_send_command.py", line 26, in netmiko_send_command
    net_connect = task.host.get_connection(CONNECTION_NAME, task.nornir.config)
                  ^^^^^^^^^^^^^^^^^^^^^^^^^^^^^^^^^^^^^^^^^^^^^^^^^^^^^^^^^^^^^
  File "C:\Users\Jithin Jose\OneDrive - NAIT\BAITS\NETW3100\NETW3100\Lib\site-packages\nornir\core\inventory.py", line 494, in get_connection
    self.open_connection(
  File "C:\Users\Jithin Jose\OneDrive - NAIT\BAITS\NETW3100\NETW3100\Lib\site-packages\nornir\core\inventory.py", line 546, in open_connection
    conn_obj.open(
  File "C:\Users\Jithin Jose\OneDrive - NAIT\BAITS\NETW3100\NETW3100\Lib\site-packages\nornir_netmiko\connections\netmiko.py", line 59, in open
    connection = ConnectHandler(**parameters)
                 ^^^^^^^^^^^^^^^^^^^^^^^^^^^^
  File "C:\Users\Jithin Jose\OneDrive - NAIT\BAITS\NETW3100\NETW3100\Lib\site-packages\netmiko\ssh_dispatcher.py", line 365, in ConnectHandler
    return ConnectionClass(*args, **kwargs)
           ^^^^^^^^^^^^^^^^^^^^^^^^^^^^^^^^
  File "C:\Users\Jithin Jose\OneDrive - NAIT\BAITS\NETW3100\NETW3100\Lib\site-packages\netmiko\base_connection.py", line 439, in __init__
    self._open()
  File "C:\Users\Jithin Jose\OneDrive - NAIT\BAITS\NETW3100\NETW3100\Lib\site-packages\netmiko\base_connection.py", line 444, in _open
    self.establish_connection()
  File "C:\Users\Jithin Jose\OneDrive - NAIT\BAITS\NETW3100\NETW3100\Lib\site-packages\netmiko\base_connection.py", line 1068, in establish_connection
    raise NetmikoTimeoutException(msg)
netmiko.exceptions.NetmikoTimeoutException: TCP connection to device failed.

Common causes of this problem are:
1. Incorrect hostname or IP address.
2. Wrong TCP port.
3. Intermediate firewall blocking access.

Device settings: cisco_ios 192.168.3.4:22



2023-11-21 17:16:25,054 -  nornir.core -     INFO -        run() - Running task 'netmiko_send_command' with args {'command_string': 'Show ip int br', 'use_textfsm': True} on 10 hosts
2023-11-21 17:16:35,113 - nornir.core.task -    ERROR -      start() - Host 'R4': task 'netmiko_send_command' failed with traceback:
Traceback (most recent call last):
  File "C:\Users\Jithin Jose\OneDrive - NAIT\BAITS\NETW3100\NETW3100\Lib\site-packages\netmiko\base_connection.py", line 1046, in establish_connection
    self.remote_conn_pre.connect(**ssh_connect_params)
  File "C:\Users\Jithin Jose\OneDrive - NAIT\BAITS\NETW3100\NETW3100\Lib\site-packages\paramiko\client.py", line 386, in connect
    sock.connect(addr)
TimeoutError: timed out

During handling of the above exception, another exception occurred:

Traceback (most recent call last):
  File "C:\Users\Jithin Jose\OneDrive - NAIT\BAITS\NETW3100\NETW3100\Lib\site-packages\nornir\core\task.py", line 99, in start
    r = self.task(self, **self.params)
        ^^^^^^^^^^^^^^^^^^^^^^^^^^^^^^
  File "C:\Users\Jithin Jose\OneDrive - NAIT\BAITS\NETW3100\NETW3100\Lib\site-packages\nornir_netmiko\tasks\netmiko_send_command.py", line 26, in netmiko_send_command
    net_connect = task.host.get_connection(CONNECTION_NAME, task.nornir.config)
                  ^^^^^^^^^^^^^^^^^^^^^^^^^^^^^^^^^^^^^^^^^^^^^^^^^^^^^^^^^^^^^
  File "C:\Users\Jithin Jose\OneDrive - NAIT\BAITS\NETW3100\NETW3100\Lib\site-packages\nornir\core\inventory.py", line 494, in get_connection
    self.open_connection(
  File "C:\Users\Jithin Jose\OneDrive - NAIT\BAITS\NETW3100\NETW3100\Lib\site-packages\nornir\core\inventory.py", line 546, in open_connection
    conn_obj.open(
  File "C:\Users\Jithin Jose\OneDrive - NAIT\BAITS\NETW3100\NETW3100\Lib\site-packages\nornir_netmiko\connections\netmiko.py", line 59, in open
    connection = ConnectHandler(**parameters)
                 ^^^^^^^^^^^^^^^^^^^^^^^^^^^^
  File "C:\Users\Jithin Jose\OneDrive - NAIT\BAITS\NETW3100\NETW3100\Lib\site-packages\netmiko\ssh_dispatcher.py", line 365, in ConnectHandler
    return ConnectionClass(*args, **kwargs)
           ^^^^^^^^^^^^^^^^^^^^^^^^^^^^^^^^
  File "C:\Users\Jithin Jose\OneDrive - NAIT\BAITS\NETW3100\NETW3100\Lib\site-packages\netmiko\base_connection.py", line 439, in __init__
    self._open()
  File "C:\Users\Jithin Jose\OneDrive - NAIT\BAITS\NETW3100\NETW3100\Lib\site-packages\netmiko\base_connection.py", line 444, in _open
    self.establish_connection()
  File "C:\Users\Jithin Jose\OneDrive - NAIT\BAITS\NETW3100\NETW3100\Lib\site-packages\netmiko\base_connection.py", line 1068, in establish_connection
    raise NetmikoTimeoutException(msg)
netmiko.exceptions.NetmikoTimeoutException: TCP connection to device failed.

Common causes of this problem are:
1. Incorrect hostname or IP address.
2. Wrong TCP port.
3. Intermediate firewall blocking access.

Device settings: cisco_ios 192.168.3.4:22



2023-11-21 17:16:35,113 - nornir.core.task -    ERROR -      start() - Host 'R5': task 'netmiko_send_command' failed with traceback:
Traceback (most recent call last):
  File "C:\Users\Jithin Jose\OneDrive - NAIT\BAITS\NETW3100\NETW3100\Lib\site-packages\netmiko\base_connection.py", line 1046, in establish_connection
    self.remote_conn_pre.connect(**ssh_connect_params)
  File "C:\Users\Jithin Jose\OneDrive - NAIT\BAITS\NETW3100\NETW3100\Lib\site-packages\paramiko\client.py", line 386, in connect
    sock.connect(addr)
TimeoutError: timed out

During handling of the above exception, another exception occurred:

Traceback (most recent call last):
  File "C:\Users\Jithin Jose\OneDrive - NAIT\BAITS\NETW3100\NETW3100\Lib\site-packages\nornir\core\task.py", line 99, in start
    r = self.task(self, **self.params)
        ^^^^^^^^^^^^^^^^^^^^^^^^^^^^^^
  File "C:\Users\Jithin Jose\OneDrive - NAIT\BAITS\NETW3100\NETW3100\Lib\site-packages\nornir_netmiko\tasks\netmiko_send_command.py", line 26, in netmiko_send_command
    net_connect = task.host.get_connection(CONNECTION_NAME, task.nornir.config)
                  ^^^^^^^^^^^^^^^^^^^^^^^^^^^^^^^^^^^^^^^^^^^^^^^^^^^^^^^^^^^^^
  File "C:\Users\Jithin Jose\OneDrive - NAIT\BAITS\NETW3100\NETW3100\Lib\site-packages\nornir\core\inventory.py", line 494, in get_connection
    self.open_connection(
  File "C:\Users\Jithin Jose\OneDrive - NAIT\BAITS\NETW3100\NETW3100\Lib\site-packages\nornir\core\inventory.py", line 546, in open_connection
    conn_obj.open(
  File "C:\Users\Jithin Jose\OneDrive - NAIT\BAITS\NETW3100\NETW3100\Lib\site-packages\nornir_netmiko\connections\netmiko.py", line 59, in open
    connection = ConnectHandler(**parameters)
                 ^^^^^^^^^^^^^^^^^^^^^^^^^^^^
  File "C:\Users\Jithin Jose\OneDrive - NAIT\BAITS\NETW3100\NETW3100\Lib\site-packages\netmiko\ssh_dispatcher.py", line 365, in ConnectHandler
    return ConnectionClass(*args, **kwargs)
           ^^^^^^^^^^^^^^^^^^^^^^^^^^^^^^^^
  File "C:\Users\Jithin Jose\OneDrive - NAIT\BAITS\NETW3100\NETW3100\Lib\site-packages\netmiko\base_connection.py", line 439, in __init__
    self._open()
  File "C:\Users\Jithin Jose\OneDrive - NAIT\BAITS\NETW3100\NETW3100\Lib\site-packages\netmiko\base_connection.py", line 444, in _open
    self.establish_connection()
  File "C:\Users\Jithin Jose\OneDrive - NAIT\BAITS\NETW3100\NETW3100\Lib\site-packages\netmiko\base_connection.py", line 1068, in establish_connection
    raise NetmikoTimeoutException(msg)
netmiko.exceptions.NetmikoTimeoutException: TCP connection to device failed.

Common causes of this problem are:
1. Incorrect hostname or IP address.
2. Wrong TCP port.
3. Intermediate firewall blocking access.

Device settings: cisco_ios 192.168.3.5:22



2023-11-21 17:16:35,113 - nornir.core.task -    ERROR -      start() - Host 'R6': task 'netmiko_send_command' failed with traceback:
Traceback (most recent call last):
  File "C:\Users\Jithin Jose\OneDrive - NAIT\BAITS\NETW3100\NETW3100\Lib\site-packages\netmiko\base_connection.py", line 1046, in establish_connection
    self.remote_conn_pre.connect(**ssh_connect_params)
  File "C:\Users\Jithin Jose\OneDrive - NAIT\BAITS\NETW3100\NETW3100\Lib\site-packages\paramiko\client.py", line 386, in connect
    sock.connect(addr)
TimeoutError: timed out

During handling of the above exception, another exception occurred:

Traceback (most recent call last):
  File "C:\Users\Jithin Jose\OneDrive - NAIT\BAITS\NETW3100\NETW3100\Lib\site-packages\nornir\core\task.py", line 99, in start
    r = self.task(self, **self.params)
        ^^^^^^^^^^^^^^^^^^^^^^^^^^^^^^
  File "C:\Users\Jithin Jose\OneDrive - NAIT\BAITS\NETW3100\NETW3100\Lib\site-packages\nornir_netmiko\tasks\netmiko_send_command.py", line 26, in netmiko_send_command
    net_connect = task.host.get_connection(CONNECTION_NAME, task.nornir.config)
                  ^^^^^^^^^^^^^^^^^^^^^^^^^^^^^^^^^^^^^^^^^^^^^^^^^^^^^^^^^^^^^
  File "C:\Users\Jithin Jose\OneDrive - NAIT\BAITS\NETW3100\NETW3100\Lib\site-packages\nornir\core\inventory.py", line 494, in get_connection
    self.open_connection(
  File "C:\Users\Jithin Jose\OneDrive - NAIT\BAITS\NETW3100\NETW3100\Lib\site-packages\nornir\core\inventory.py", line 546, in open_connection
    conn_obj.open(
  File "C:\Users\Jithin Jose\OneDrive - NAIT\BAITS\NETW3100\NETW3100\Lib\site-packages\nornir_netmiko\connections\netmiko.py", line 59, in open
    connection = ConnectHandler(**parameters)
                 ^^^^^^^^^^^^^^^^^^^^^^^^^^^^
  File "C:\Users\Jithin Jose\OneDrive - NAIT\BAITS\NETW3100\NETW3100\Lib\site-packages\netmiko\ssh_dispatcher.py", line 365, in ConnectHandler
    return ConnectionClass(*args, **kwargs)
           ^^^^^^^^^^^^^^^^^^^^^^^^^^^^^^^^
  File "C:\Users\Jithin Jose\OneDrive - NAIT\BAITS\NETW3100\NETW3100\Lib\site-packages\netmiko\base_connection.py", line 439, in __init__
    self._open()
  File "C:\Users\Jithin Jose\OneDrive - NAIT\BAITS\NETW3100\NETW3100\Lib\site-packages\netmiko\base_connection.py", line 444, in _open
    self.establish_connection()
  File "C:\Users\Jithin Jose\OneDrive - NAIT\BAITS\NETW3100\NETW3100\Lib\site-packages\netmiko\base_connection.py", line 1068, in establish_connection
    raise NetmikoTimeoutException(msg)
netmiko.exceptions.NetmikoTimeoutException: TCP connection to device failed.

Common causes of this problem are:
1. Incorrect hostname or IP address.
2. Wrong TCP port.
3. Intermediate firewall blocking access.

Device settings: cisco_ios 192.168.3.6:22



2023-11-21 17:16:35,113 - nornir.core.task -    ERROR -      start() - Host 'SW2': task 'netmiko_send_command' failed with traceback:
Traceback (most recent call last):
  File "C:\Users\Jithin Jose\OneDrive - NAIT\BAITS\NETW3100\NETW3100\Lib\site-packages\netmiko\base_connection.py", line 1046, in establish_connection
    self.remote_conn_pre.connect(**ssh_connect_params)
  File "C:\Users\Jithin Jose\OneDrive - NAIT\BAITS\NETW3100\NETW3100\Lib\site-packages\paramiko\client.py", line 386, in connect
    sock.connect(addr)
TimeoutError: timed out

During handling of the above exception, another exception occurred:

Traceback (most recent call last):
  File "C:\Users\Jithin Jose\OneDrive - NAIT\BAITS\NETW3100\NETW3100\Lib\site-packages\nornir\core\task.py", line 99, in start
    r = self.task(self, **self.params)
        ^^^^^^^^^^^^^^^^^^^^^^^^^^^^^^
  File "C:\Users\Jithin Jose\OneDrive - NAIT\BAITS\NETW3100\NETW3100\Lib\site-packages\nornir_netmiko\tasks\netmiko_send_command.py", line 26, in netmiko_send_command
    net_connect = task.host.get_connection(CONNECTION_NAME, task.nornir.config)
                  ^^^^^^^^^^^^^^^^^^^^^^^^^^^^^^^^^^^^^^^^^^^^^^^^^^^^^^^^^^^^^
  File "C:\Users\Jithin Jose\OneDrive - NAIT\BAITS\NETW3100\NETW3100\Lib\site-packages\nornir\core\inventory.py", line 494, in get_connection
    self.open_connection(
  File "C:\Users\Jithin Jose\OneDrive - NAIT\BAITS\NETW3100\NETW3100\Lib\site-packages\nornir\core\inventory.py", line 546, in open_connection
    conn_obj.open(
  File "C:\Users\Jithin Jose\OneDrive - NAIT\BAITS\NETW3100\NETW3100\Lib\site-packages\nornir_netmiko\connections\netmiko.py", line 59, in open
    connection = ConnectHandler(**parameters)
                 ^^^^^^^^^^^^^^^^^^^^^^^^^^^^
  File "C:\Users\Jithin Jose\OneDrive - NAIT\BAITS\NETW3100\NETW3100\Lib\site-packages\netmiko\ssh_dispatcher.py", line 365, in ConnectHandler
    return ConnectionClass(*args, **kwargs)
           ^^^^^^^^^^^^^^^^^^^^^^^^^^^^^^^^
  File "C:\Users\Jithin Jose\OneDrive - NAIT\BAITS\NETW3100\NETW3100\Lib\site-packages\netmiko\base_connection.py", line 439, in __init__
    self._open()
  File "C:\Users\Jithin Jose\OneDrive - NAIT\BAITS\NETW3100\NETW3100\Lib\site-packages\netmiko\base_connection.py", line 444, in _open
    self.establish_connection()
  File "C:\Users\Jithin Jose\OneDrive - NAIT\BAITS\NETW3100\NETW3100\Lib\site-packages\netmiko\base_connection.py", line 1068, in establish_connection
    raise NetmikoTimeoutException(msg)
netmiko.exceptions.NetmikoTimeoutException: TCP connection to device failed.

Common causes of this problem are:
1. Incorrect hostname or IP address.
2. Wrong TCP port.
3. Intermediate firewall blocking access.

Device settings: cisco_ios 192.168.3.12:22



2023-11-21 17:19:11,163 -  nornir.core -     INFO -        run() - Running task 'netmiko_send_command' with args {'command_string': 'Show ver', 'use_textfsm': True} on 10 hosts
2023-11-21 17:19:21,169 - nornir.core.task -    ERROR -      start() - Host 'R6': task 'netmiko_send_command' failed with traceback:
Traceback (most recent call last):
  File "C:\Users\Jithin Jose\OneDrive - NAIT\BAITS\NETW3100\NETW3100\Lib\site-packages\netmiko\base_connection.py", line 1046, in establish_connection
    self.remote_conn_pre.connect(**ssh_connect_params)
  File "C:\Users\Jithin Jose\OneDrive - NAIT\BAITS\NETW3100\NETW3100\Lib\site-packages\paramiko\client.py", line 386, in connect
    sock.connect(addr)
TimeoutError: timed out

During handling of the above exception, another exception occurred:

Traceback (most recent call last):
  File "C:\Users\Jithin Jose\OneDrive - NAIT\BAITS\NETW3100\NETW3100\Lib\site-packages\nornir\core\task.py", line 99, in start
    r = self.task(self, **self.params)
        ^^^^^^^^^^^^^^^^^^^^^^^^^^^^^^
  File "C:\Users\Jithin Jose\OneDrive - NAIT\BAITS\NETW3100\NETW3100\Lib\site-packages\nornir_netmiko\tasks\netmiko_send_command.py", line 26, in netmiko_send_command
    net_connect = task.host.get_connection(CONNECTION_NAME, task.nornir.config)
                  ^^^^^^^^^^^^^^^^^^^^^^^^^^^^^^^^^^^^^^^^^^^^^^^^^^^^^^^^^^^^^
  File "C:\Users\Jithin Jose\OneDrive - NAIT\BAITS\NETW3100\NETW3100\Lib\site-packages\nornir\core\inventory.py", line 494, in get_connection
    self.open_connection(
  File "C:\Users\Jithin Jose\OneDrive - NAIT\BAITS\NETW3100\NETW3100\Lib\site-packages\nornir\core\inventory.py", line 546, in open_connection
    conn_obj.open(
  File "C:\Users\Jithin Jose\OneDrive - NAIT\BAITS\NETW3100\NETW3100\Lib\site-packages\nornir_netmiko\connections\netmiko.py", line 59, in open
    connection = ConnectHandler(**parameters)
                 ^^^^^^^^^^^^^^^^^^^^^^^^^^^^
  File "C:\Users\Jithin Jose\OneDrive - NAIT\BAITS\NETW3100\NETW3100\Lib\site-packages\netmiko\ssh_dispatcher.py", line 365, in ConnectHandler
    return ConnectionClass(*args, **kwargs)
           ^^^^^^^^^^^^^^^^^^^^^^^^^^^^^^^^
  File "C:\Users\Jithin Jose\OneDrive - NAIT\BAITS\NETW3100\NETW3100\Lib\site-packages\netmiko\base_connection.py", line 439, in __init__
    self._open()
  File "C:\Users\Jithin Jose\OneDrive - NAIT\BAITS\NETW3100\NETW3100\Lib\site-packages\netmiko\base_connection.py", line 444, in _open
    self.establish_connection()
  File "C:\Users\Jithin Jose\OneDrive - NAIT\BAITS\NETW3100\NETW3100\Lib\site-packages\netmiko\base_connection.py", line 1068, in establish_connection
    raise NetmikoTimeoutException(msg)
netmiko.exceptions.NetmikoTimeoutException: TCP connection to device failed.

Common causes of this problem are:
1. Incorrect hostname or IP address.
2. Wrong TCP port.
3. Intermediate firewall blocking access.

Device settings: cisco_ios 192.168.3.6:22



2023-11-21 17:19:21,169 - nornir.core.task -    ERROR -      start() - Host 'SW2': task 'netmiko_send_command' failed with traceback:
Traceback (most recent call last):
  File "C:\Users\Jithin Jose\OneDrive - NAIT\BAITS\NETW3100\NETW3100\Lib\site-packages\netmiko\base_connection.py", line 1046, in establish_connection
    self.remote_conn_pre.connect(**ssh_connect_params)
  File "C:\Users\Jithin Jose\OneDrive - NAIT\BAITS\NETW3100\NETW3100\Lib\site-packages\paramiko\client.py", line 386, in connect
    sock.connect(addr)
TimeoutError: timed out

During handling of the above exception, another exception occurred:

Traceback (most recent call last):
  File "C:\Users\Jithin Jose\OneDrive - NAIT\BAITS\NETW3100\NETW3100\Lib\site-packages\nornir\core\task.py", line 99, in start
    r = self.task(self, **self.params)
        ^^^^^^^^^^^^^^^^^^^^^^^^^^^^^^
  File "C:\Users\Jithin Jose\OneDrive - NAIT\BAITS\NETW3100\NETW3100\Lib\site-packages\nornir_netmiko\tasks\netmiko_send_command.py", line 26, in netmiko_send_command
    net_connect = task.host.get_connection(CONNECTION_NAME, task.nornir.config)
                  ^^^^^^^^^^^^^^^^^^^^^^^^^^^^^^^^^^^^^^^^^^^^^^^^^^^^^^^^^^^^^
  File "C:\Users\Jithin Jose\OneDrive - NAIT\BAITS\NETW3100\NETW3100\Lib\site-packages\nornir\core\inventory.py", line 494, in get_connection
    self.open_connection(
  File "C:\Users\Jithin Jose\OneDrive - NAIT\BAITS\NETW3100\NETW3100\Lib\site-packages\nornir\core\inventory.py", line 546, in open_connection
    conn_obj.open(
  File "C:\Users\Jithin Jose\OneDrive - NAIT\BAITS\NETW3100\NETW3100\Lib\site-packages\nornir_netmiko\connections\netmiko.py", line 59, in open
    connection = ConnectHandler(**parameters)
                 ^^^^^^^^^^^^^^^^^^^^^^^^^^^^
  File "C:\Users\Jithin Jose\OneDrive - NAIT\BAITS\NETW3100\NETW3100\Lib\site-packages\netmiko\ssh_dispatcher.py", line 365, in ConnectHandler
    return ConnectionClass(*args, **kwargs)
           ^^^^^^^^^^^^^^^^^^^^^^^^^^^^^^^^
  File "C:\Users\Jithin Jose\OneDrive - NAIT\BAITS\NETW3100\NETW3100\Lib\site-packages\netmiko\base_connection.py", line 439, in __init__
    self._open()
  File "C:\Users\Jithin Jose\OneDrive - NAIT\BAITS\NETW3100\NETW3100\Lib\site-packages\netmiko\base_connection.py", line 444, in _open
    self.establish_connection()
  File "C:\Users\Jithin Jose\OneDrive - NAIT\BAITS\NETW3100\NETW3100\Lib\site-packages\netmiko\base_connection.py", line 1068, in establish_connection
    raise NetmikoTimeoutException(msg)
netmiko.exceptions.NetmikoTimeoutException: TCP connection to device failed.

Common causes of this problem are:
1. Incorrect hostname or IP address.
2. Wrong TCP port.
3. Intermediate firewall blocking access.

Device settings: cisco_ios 192.168.3.12:22



2023-11-21 17:19:21,173 - nornir.core.task -    ERROR -      start() - Host 'R5': task 'netmiko_send_command' failed with traceback:
Traceback (most recent call last):
  File "C:\Users\Jithin Jose\OneDrive - NAIT\BAITS\NETW3100\NETW3100\Lib\site-packages\netmiko\base_connection.py", line 1046, in establish_connection
    self.remote_conn_pre.connect(**ssh_connect_params)
  File "C:\Users\Jithin Jose\OneDrive - NAIT\BAITS\NETW3100\NETW3100\Lib\site-packages\paramiko\client.py", line 386, in connect
    sock.connect(addr)
TimeoutError: timed out

During handling of the above exception, another exception occurred:

Traceback (most recent call last):
  File "C:\Users\Jithin Jose\OneDrive - NAIT\BAITS\NETW3100\NETW3100\Lib\site-packages\nornir\core\task.py", line 99, in start
    r = self.task(self, **self.params)
        ^^^^^^^^^^^^^^^^^^^^^^^^^^^^^^
  File "C:\Users\Jithin Jose\OneDrive - NAIT\BAITS\NETW3100\NETW3100\Lib\site-packages\nornir_netmiko\tasks\netmiko_send_command.py", line 26, in netmiko_send_command
    net_connect = task.host.get_connection(CONNECTION_NAME, task.nornir.config)
                  ^^^^^^^^^^^^^^^^^^^^^^^^^^^^^^^^^^^^^^^^^^^^^^^^^^^^^^^^^^^^^
  File "C:\Users\Jithin Jose\OneDrive - NAIT\BAITS\NETW3100\NETW3100\Lib\site-packages\nornir\core\inventory.py", line 494, in get_connection
    self.open_connection(
  File "C:\Users\Jithin Jose\OneDrive - NAIT\BAITS\NETW3100\NETW3100\Lib\site-packages\nornir\core\inventory.py", line 546, in open_connection
    conn_obj.open(
  File "C:\Users\Jithin Jose\OneDrive - NAIT\BAITS\NETW3100\NETW3100\Lib\site-packages\nornir_netmiko\connections\netmiko.py", line 59, in open
    connection = ConnectHandler(**parameters)
                 ^^^^^^^^^^^^^^^^^^^^^^^^^^^^
  File "C:\Users\Jithin Jose\OneDrive - NAIT\BAITS\NETW3100\NETW3100\Lib\site-packages\netmiko\ssh_dispatcher.py", line 365, in ConnectHandler
    return ConnectionClass(*args, **kwargs)
           ^^^^^^^^^^^^^^^^^^^^^^^^^^^^^^^^
  File "C:\Users\Jithin Jose\OneDrive - NAIT\BAITS\NETW3100\NETW3100\Lib\site-packages\netmiko\base_connection.py", line 439, in __init__
    self._open()
  File "C:\Users\Jithin Jose\OneDrive - NAIT\BAITS\NETW3100\NETW3100\Lib\site-packages\netmiko\base_connection.py", line 444, in _open
    self.establish_connection()
  File "C:\Users\Jithin Jose\OneDrive - NAIT\BAITS\NETW3100\NETW3100\Lib\site-packages\netmiko\base_connection.py", line 1068, in establish_connection
    raise NetmikoTimeoutException(msg)
netmiko.exceptions.NetmikoTimeoutException: TCP connection to device failed.

Common causes of this problem are:
1. Incorrect hostname or IP address.
2. Wrong TCP port.
3. Intermediate firewall blocking access.

Device settings: cisco_ios 192.168.3.5:22



2023-11-21 17:19:21,175 - nornir.core.task -    ERROR -      start() - Host 'R4': task 'netmiko_send_command' failed with traceback:
Traceback (most recent call last):
  File "C:\Users\Jithin Jose\OneDrive - NAIT\BAITS\NETW3100\NETW3100\Lib\site-packages\netmiko\base_connection.py", line 1046, in establish_connection
    self.remote_conn_pre.connect(**ssh_connect_params)
  File "C:\Users\Jithin Jose\OneDrive - NAIT\BAITS\NETW3100\NETW3100\Lib\site-packages\paramiko\client.py", line 386, in connect
    sock.connect(addr)
TimeoutError: timed out

During handling of the above exception, another exception occurred:

Traceback (most recent call last):
  File "C:\Users\Jithin Jose\OneDrive - NAIT\BAITS\NETW3100\NETW3100\Lib\site-packages\nornir\core\task.py", line 99, in start
    r = self.task(self, **self.params)
        ^^^^^^^^^^^^^^^^^^^^^^^^^^^^^^
  File "C:\Users\Jithin Jose\OneDrive - NAIT\BAITS\NETW3100\NETW3100\Lib\site-packages\nornir_netmiko\tasks\netmiko_send_command.py", line 26, in netmiko_send_command
    net_connect = task.host.get_connection(CONNECTION_NAME, task.nornir.config)
                  ^^^^^^^^^^^^^^^^^^^^^^^^^^^^^^^^^^^^^^^^^^^^^^^^^^^^^^^^^^^^^
  File "C:\Users\Jithin Jose\OneDrive - NAIT\BAITS\NETW3100\NETW3100\Lib\site-packages\nornir\core\inventory.py", line 494, in get_connection
    self.open_connection(
  File "C:\Users\Jithin Jose\OneDrive - NAIT\BAITS\NETW3100\NETW3100\Lib\site-packages\nornir\core\inventory.py", line 546, in open_connection
    conn_obj.open(
  File "C:\Users\Jithin Jose\OneDrive - NAIT\BAITS\NETW3100\NETW3100\Lib\site-packages\nornir_netmiko\connections\netmiko.py", line 59, in open
    connection = ConnectHandler(**parameters)
                 ^^^^^^^^^^^^^^^^^^^^^^^^^^^^
  File "C:\Users\Jithin Jose\OneDrive - NAIT\BAITS\NETW3100\NETW3100\Lib\site-packages\netmiko\ssh_dispatcher.py", line 365, in ConnectHandler
    return ConnectionClass(*args, **kwargs)
           ^^^^^^^^^^^^^^^^^^^^^^^^^^^^^^^^
  File "C:\Users\Jithin Jose\OneDrive - NAIT\BAITS\NETW3100\NETW3100\Lib\site-packages\netmiko\base_connection.py", line 439, in __init__
    self._open()
  File "C:\Users\Jithin Jose\OneDrive - NAIT\BAITS\NETW3100\NETW3100\Lib\site-packages\netmiko\base_connection.py", line 444, in _open
    self.establish_connection()
  File "C:\Users\Jithin Jose\OneDrive - NAIT\BAITS\NETW3100\NETW3100\Lib\site-packages\netmiko\base_connection.py", line 1068, in establish_connection
    raise NetmikoTimeoutException(msg)
netmiko.exceptions.NetmikoTimeoutException: TCP connection to device failed.

Common causes of this problem are:
1. Incorrect hostname or IP address.
2. Wrong TCP port.
3. Intermediate firewall blocking access.

Device settings: cisco_ios 192.168.3.4:22



2023-11-21 17:24:29,658 -  nornir.core -     INFO -        run() - Running task 'netmiko_send_command' with args {'command_string': 'Show ip int br', 'use_textfsm': True} on 10 hosts
2023-11-21 17:24:39,708 - nornir.core.task -    ERROR -      start() - Host 'R4': task 'netmiko_send_command' failed with traceback:
Traceback (most recent call last):
  File "C:\Users\Jithin Jose\OneDrive - NAIT\BAITS\NETW3100\NETW3100\Lib\site-packages\netmiko\base_connection.py", line 1046, in establish_connection
    self.remote_conn_pre.connect(**ssh_connect_params)
  File "C:\Users\Jithin Jose\OneDrive - NAIT\BAITS\NETW3100\NETW3100\Lib\site-packages\paramiko\client.py", line 386, in connect
    sock.connect(addr)
TimeoutError: timed out

During handling of the above exception, another exception occurred:

Traceback (most recent call last):
  File "C:\Users\Jithin Jose\OneDrive - NAIT\BAITS\NETW3100\NETW3100\Lib\site-packages\nornir\core\task.py", line 99, in start
    r = self.task(self, **self.params)
        ^^^^^^^^^^^^^^^^^^^^^^^^^^^^^^
  File "C:\Users\Jithin Jose\OneDrive - NAIT\BAITS\NETW3100\NETW3100\Lib\site-packages\nornir_netmiko\tasks\netmiko_send_command.py", line 26, in netmiko_send_command
    net_connect = task.host.get_connection(CONNECTION_NAME, task.nornir.config)
                  ^^^^^^^^^^^^^^^^^^^^^^^^^^^^^^^^^^^^^^^^^^^^^^^^^^^^^^^^^^^^^
  File "C:\Users\Jithin Jose\OneDrive - NAIT\BAITS\NETW3100\NETW3100\Lib\site-packages\nornir\core\inventory.py", line 494, in get_connection
    self.open_connection(
  File "C:\Users\Jithin Jose\OneDrive - NAIT\BAITS\NETW3100\NETW3100\Lib\site-packages\nornir\core\inventory.py", line 546, in open_connection
    conn_obj.open(
  File "C:\Users\Jithin Jose\OneDrive - NAIT\BAITS\NETW3100\NETW3100\Lib\site-packages\nornir_netmiko\connections\netmiko.py", line 59, in open
    connection = ConnectHandler(**parameters)
                 ^^^^^^^^^^^^^^^^^^^^^^^^^^^^
  File "C:\Users\Jithin Jose\OneDrive - NAIT\BAITS\NETW3100\NETW3100\Lib\site-packages\netmiko\ssh_dispatcher.py", line 365, in ConnectHandler
    return ConnectionClass(*args, **kwargs)
           ^^^^^^^^^^^^^^^^^^^^^^^^^^^^^^^^
  File "C:\Users\Jithin Jose\OneDrive - NAIT\BAITS\NETW3100\NETW3100\Lib\site-packages\netmiko\base_connection.py", line 439, in __init__
    self._open()
  File "C:\Users\Jithin Jose\OneDrive - NAIT\BAITS\NETW3100\NETW3100\Lib\site-packages\netmiko\base_connection.py", line 444, in _open
    self.establish_connection()
  File "C:\Users\Jithin Jose\OneDrive - NAIT\BAITS\NETW3100\NETW3100\Lib\site-packages\netmiko\base_connection.py", line 1068, in establish_connection
    raise NetmikoTimeoutException(msg)
netmiko.exceptions.NetmikoTimeoutException: TCP connection to device failed.

Common causes of this problem are:
1. Incorrect hostname or IP address.
2. Wrong TCP port.
3. Intermediate firewall blocking access.

Device settings: cisco_ios 192.168.3.4:22



2023-11-21 17:24:39,708 - nornir.core.task -    ERROR -      start() - Host 'R6': task 'netmiko_send_command' failed with traceback:
Traceback (most recent call last):
  File "C:\Users\Jithin Jose\OneDrive - NAIT\BAITS\NETW3100\NETW3100\Lib\site-packages\netmiko\base_connection.py", line 1046, in establish_connection
    self.remote_conn_pre.connect(**ssh_connect_params)
  File "C:\Users\Jithin Jose\OneDrive - NAIT\BAITS\NETW3100\NETW3100\Lib\site-packages\paramiko\client.py", line 386, in connect
    sock.connect(addr)
TimeoutError: timed out

During handling of the above exception, another exception occurred:

Traceback (most recent call last):
  File "C:\Users\Jithin Jose\OneDrive - NAIT\BAITS\NETW3100\NETW3100\Lib\site-packages\nornir\core\task.py", line 99, in start
    r = self.task(self, **self.params)
        ^^^^^^^^^^^^^^^^^^^^^^^^^^^^^^
  File "C:\Users\Jithin Jose\OneDrive - NAIT\BAITS\NETW3100\NETW3100\Lib\site-packages\nornir_netmiko\tasks\netmiko_send_command.py", line 26, in netmiko_send_command
    net_connect = task.host.get_connection(CONNECTION_NAME, task.nornir.config)
                  ^^^^^^^^^^^^^^^^^^^^^^^^^^^^^^^^^^^^^^^^^^^^^^^^^^^^^^^^^^^^^
  File "C:\Users\Jithin Jose\OneDrive - NAIT\BAITS\NETW3100\NETW3100\Lib\site-packages\nornir\core\inventory.py", line 494, in get_connection
    self.open_connection(
  File "C:\Users\Jithin Jose\OneDrive - NAIT\BAITS\NETW3100\NETW3100\Lib\site-packages\nornir\core\inventory.py", line 546, in open_connection
    conn_obj.open(
  File "C:\Users\Jithin Jose\OneDrive - NAIT\BAITS\NETW3100\NETW3100\Lib\site-packages\nornir_netmiko\connections\netmiko.py", line 59, in open
    connection = ConnectHandler(**parameters)
                 ^^^^^^^^^^^^^^^^^^^^^^^^^^^^
  File "C:\Users\Jithin Jose\OneDrive - NAIT\BAITS\NETW3100\NETW3100\Lib\site-packages\netmiko\ssh_dispatcher.py", line 365, in ConnectHandler
    return ConnectionClass(*args, **kwargs)
           ^^^^^^^^^^^^^^^^^^^^^^^^^^^^^^^^
  File "C:\Users\Jithin Jose\OneDrive - NAIT\BAITS\NETW3100\NETW3100\Lib\site-packages\netmiko\base_connection.py", line 439, in __init__
    self._open()
  File "C:\Users\Jithin Jose\OneDrive - NAIT\BAITS\NETW3100\NETW3100\Lib\site-packages\netmiko\base_connection.py", line 444, in _open
    self.establish_connection()
  File "C:\Users\Jithin Jose\OneDrive - NAIT\BAITS\NETW3100\NETW3100\Lib\site-packages\netmiko\base_connection.py", line 1068, in establish_connection
    raise NetmikoTimeoutException(msg)
netmiko.exceptions.NetmikoTimeoutException: TCP connection to device failed.

Common causes of this problem are:
1. Incorrect hostname or IP address.
2. Wrong TCP port.
3. Intermediate firewall blocking access.

Device settings: cisco_ios 192.168.3.6:22



2023-11-21 17:24:39,708 - nornir.core.task -    ERROR -      start() - Host 'R5': task 'netmiko_send_command' failed with traceback:
Traceback (most recent call last):
  File "C:\Users\Jithin Jose\OneDrive - NAIT\BAITS\NETW3100\NETW3100\Lib\site-packages\netmiko\base_connection.py", line 1046, in establish_connection
    self.remote_conn_pre.connect(**ssh_connect_params)
  File "C:\Users\Jithin Jose\OneDrive - NAIT\BAITS\NETW3100\NETW3100\Lib\site-packages\paramiko\client.py", line 386, in connect
    sock.connect(addr)
TimeoutError: timed out

During handling of the above exception, another exception occurred:

Traceback (most recent call last):
  File "C:\Users\Jithin Jose\OneDrive - NAIT\BAITS\NETW3100\NETW3100\Lib\site-packages\nornir\core\task.py", line 99, in start
    r = self.task(self, **self.params)
        ^^^^^^^^^^^^^^^^^^^^^^^^^^^^^^
  File "C:\Users\Jithin Jose\OneDrive - NAIT\BAITS\NETW3100\NETW3100\Lib\site-packages\nornir_netmiko\tasks\netmiko_send_command.py", line 26, in netmiko_send_command
    net_connect = task.host.get_connection(CONNECTION_NAME, task.nornir.config)
                  ^^^^^^^^^^^^^^^^^^^^^^^^^^^^^^^^^^^^^^^^^^^^^^^^^^^^^^^^^^^^^
  File "C:\Users\Jithin Jose\OneDrive - NAIT\BAITS\NETW3100\NETW3100\Lib\site-packages\nornir\core\inventory.py", line 494, in get_connection
    self.open_connection(
  File "C:\Users\Jithin Jose\OneDrive - NAIT\BAITS\NETW3100\NETW3100\Lib\site-packages\nornir\core\inventory.py", line 546, in open_connection
    conn_obj.open(
  File "C:\Users\Jithin Jose\OneDrive - NAIT\BAITS\NETW3100\NETW3100\Lib\site-packages\nornir_netmiko\connections\netmiko.py", line 59, in open
    connection = ConnectHandler(**parameters)
                 ^^^^^^^^^^^^^^^^^^^^^^^^^^^^
  File "C:\Users\Jithin Jose\OneDrive - NAIT\BAITS\NETW3100\NETW3100\Lib\site-packages\netmiko\ssh_dispatcher.py", line 365, in ConnectHandler
    return ConnectionClass(*args, **kwargs)
           ^^^^^^^^^^^^^^^^^^^^^^^^^^^^^^^^
  File "C:\Users\Jithin Jose\OneDrive - NAIT\BAITS\NETW3100\NETW3100\Lib\site-packages\netmiko\base_connection.py", line 439, in __init__
    self._open()
  File "C:\Users\Jithin Jose\OneDrive - NAIT\BAITS\NETW3100\NETW3100\Lib\site-packages\netmiko\base_connection.py", line 444, in _open
    self.establish_connection()
  File "C:\Users\Jithin Jose\OneDrive - NAIT\BAITS\NETW3100\NETW3100\Lib\site-packages\netmiko\base_connection.py", line 1068, in establish_connection
    raise NetmikoTimeoutException(msg)
netmiko.exceptions.NetmikoTimeoutException: TCP connection to device failed.

Common causes of this problem are:
1. Incorrect hostname or IP address.
2. Wrong TCP port.
3. Intermediate firewall blocking access.

Device settings: cisco_ios 192.168.3.5:22



2023-11-21 17:24:39,740 - nornir.core.task -    ERROR -      start() - Host 'SW2': task 'netmiko_send_command' failed with traceback:
Traceback (most recent call last):
  File "C:\Users\Jithin Jose\OneDrive - NAIT\BAITS\NETW3100\NETW3100\Lib\site-packages\netmiko\base_connection.py", line 1046, in establish_connection
    self.remote_conn_pre.connect(**ssh_connect_params)
  File "C:\Users\Jithin Jose\OneDrive - NAIT\BAITS\NETW3100\NETW3100\Lib\site-packages\paramiko\client.py", line 386, in connect
    sock.connect(addr)
TimeoutError: timed out

During handling of the above exception, another exception occurred:

Traceback (most recent call last):
  File "C:\Users\Jithin Jose\OneDrive - NAIT\BAITS\NETW3100\NETW3100\Lib\site-packages\nornir\core\task.py", line 99, in start
    r = self.task(self, **self.params)
        ^^^^^^^^^^^^^^^^^^^^^^^^^^^^^^
  File "C:\Users\Jithin Jose\OneDrive - NAIT\BAITS\NETW3100\NETW3100\Lib\site-packages\nornir_netmiko\tasks\netmiko_send_command.py", line 26, in netmiko_send_command
    net_connect = task.host.get_connection(CONNECTION_NAME, task.nornir.config)
                  ^^^^^^^^^^^^^^^^^^^^^^^^^^^^^^^^^^^^^^^^^^^^^^^^^^^^^^^^^^^^^
  File "C:\Users\Jithin Jose\OneDrive - NAIT\BAITS\NETW3100\NETW3100\Lib\site-packages\nornir\core\inventory.py", line 494, in get_connection
    self.open_connection(
  File "C:\Users\Jithin Jose\OneDrive - NAIT\BAITS\NETW3100\NETW3100\Lib\site-packages\nornir\core\inventory.py", line 546, in open_connection
    conn_obj.open(
  File "C:\Users\Jithin Jose\OneDrive - NAIT\BAITS\NETW3100\NETW3100\Lib\site-packages\nornir_netmiko\connections\netmiko.py", line 59, in open
    connection = ConnectHandler(**parameters)
                 ^^^^^^^^^^^^^^^^^^^^^^^^^^^^
  File "C:\Users\Jithin Jose\OneDrive - NAIT\BAITS\NETW3100\NETW3100\Lib\site-packages\netmiko\ssh_dispatcher.py", line 365, in ConnectHandler
    return ConnectionClass(*args, **kwargs)
           ^^^^^^^^^^^^^^^^^^^^^^^^^^^^^^^^
  File "C:\Users\Jithin Jose\OneDrive - NAIT\BAITS\NETW3100\NETW3100\Lib\site-packages\netmiko\base_connection.py", line 439, in __init__
    self._open()
  File "C:\Users\Jithin Jose\OneDrive - NAIT\BAITS\NETW3100\NETW3100\Lib\site-packages\netmiko\base_connection.py", line 444, in _open
    self.establish_connection()
  File "C:\Users\Jithin Jose\OneDrive - NAIT\BAITS\NETW3100\NETW3100\Lib\site-packages\netmiko\base_connection.py", line 1068, in establish_connection
    raise NetmikoTimeoutException(msg)
netmiko.exceptions.NetmikoTimeoutException: TCP connection to device failed.

Common causes of this problem are:
1. Incorrect hostname or IP address.
2. Wrong TCP port.
3. Intermediate firewall blocking access.

Device settings: cisco_ios 192.168.3.12:22



2023-11-21 17:29:34,498 -  nornir.core -     INFO -        run() - Running task 'netmiko_send_command' with args {'command_string': 'Show ip int br', 'use_textfsm': True} on 10 hosts
2023-11-21 17:29:44,509 - nornir.core.task -    ERROR -      start() - Host 'SW2': task 'netmiko_send_command' failed with traceback:
Traceback (most recent call last):
  File "C:\Users\Jithin Jose\OneDrive - NAIT\BAITS\NETW3100\NETW3100\Lib\site-packages\netmiko\base_connection.py", line 1046, in establish_connection
    self.remote_conn_pre.connect(**ssh_connect_params)
  File "C:\Users\Jithin Jose\OneDrive - NAIT\BAITS\NETW3100\NETW3100\Lib\site-packages\paramiko\client.py", line 386, in connect
    sock.connect(addr)
TimeoutError: timed out

During handling of the above exception, another exception occurred:

Traceback (most recent call last):
  File "C:\Users\Jithin Jose\OneDrive - NAIT\BAITS\NETW3100\NETW3100\Lib\site-packages\nornir\core\task.py", line 99, in start
    r = self.task(self, **self.params)
        ^^^^^^^^^^^^^^^^^^^^^^^^^^^^^^
  File "C:\Users\Jithin Jose\OneDrive - NAIT\BAITS\NETW3100\NETW3100\Lib\site-packages\nornir_netmiko\tasks\netmiko_send_command.py", line 26, in netmiko_send_command
    net_connect = task.host.get_connection(CONNECTION_NAME, task.nornir.config)
                  ^^^^^^^^^^^^^^^^^^^^^^^^^^^^^^^^^^^^^^^^^^^^^^^^^^^^^^^^^^^^^
  File "C:\Users\Jithin Jose\OneDrive - NAIT\BAITS\NETW3100\NETW3100\Lib\site-packages\nornir\core\inventory.py", line 494, in get_connection
    self.open_connection(
  File "C:\Users\Jithin Jose\OneDrive - NAIT\BAITS\NETW3100\NETW3100\Lib\site-packages\nornir\core\inventory.py", line 546, in open_connection
    conn_obj.open(
  File "C:\Users\Jithin Jose\OneDrive - NAIT\BAITS\NETW3100\NETW3100\Lib\site-packages\nornir_netmiko\connections\netmiko.py", line 59, in open
    connection = ConnectHandler(**parameters)
                 ^^^^^^^^^^^^^^^^^^^^^^^^^^^^
  File "C:\Users\Jithin Jose\OneDrive - NAIT\BAITS\NETW3100\NETW3100\Lib\site-packages\netmiko\ssh_dispatcher.py", line 365, in ConnectHandler
    return ConnectionClass(*args, **kwargs)
           ^^^^^^^^^^^^^^^^^^^^^^^^^^^^^^^^
  File "C:\Users\Jithin Jose\OneDrive - NAIT\BAITS\NETW3100\NETW3100\Lib\site-packages\netmiko\base_connection.py", line 439, in __init__
    self._open()
  File "C:\Users\Jithin Jose\OneDrive - NAIT\BAITS\NETW3100\NETW3100\Lib\site-packages\netmiko\base_connection.py", line 444, in _open
    self.establish_connection()
  File "C:\Users\Jithin Jose\OneDrive - NAIT\BAITS\NETW3100\NETW3100\Lib\site-packages\netmiko\base_connection.py", line 1068, in establish_connection
    raise NetmikoTimeoutException(msg)
netmiko.exceptions.NetmikoTimeoutException: TCP connection to device failed.

Common causes of this problem are:
1. Incorrect hostname or IP address.
2. Wrong TCP port.
3. Intermediate firewall blocking access.

Device settings: cisco_ios 192.168.3.12:22



2023-11-21 17:29:44,509 - nornir.core.task -    ERROR -      start() - Host 'R6': task 'netmiko_send_command' failed with traceback:
Traceback (most recent call last):
  File "C:\Users\Jithin Jose\OneDrive - NAIT\BAITS\NETW3100\NETW3100\Lib\site-packages\netmiko\base_connection.py", line 1046, in establish_connection
    self.remote_conn_pre.connect(**ssh_connect_params)
  File "C:\Users\Jithin Jose\OneDrive - NAIT\BAITS\NETW3100\NETW3100\Lib\site-packages\paramiko\client.py", line 386, in connect
    sock.connect(addr)
TimeoutError: timed out

During handling of the above exception, another exception occurred:

Traceback (most recent call last):
  File "C:\Users\Jithin Jose\OneDrive - NAIT\BAITS\NETW3100\NETW3100\Lib\site-packages\nornir\core\task.py", line 99, in start
    r = self.task(self, **self.params)
        ^^^^^^^^^^^^^^^^^^^^^^^^^^^^^^
  File "C:\Users\Jithin Jose\OneDrive - NAIT\BAITS\NETW3100\NETW3100\Lib\site-packages\nornir_netmiko\tasks\netmiko_send_command.py", line 26, in netmiko_send_command
    net_connect = task.host.get_connection(CONNECTION_NAME, task.nornir.config)
                  ^^^^^^^^^^^^^^^^^^^^^^^^^^^^^^^^^^^^^^^^^^^^^^^^^^^^^^^^^^^^^
  File "C:\Users\Jithin Jose\OneDrive - NAIT\BAITS\NETW3100\NETW3100\Lib\site-packages\nornir\core\inventory.py", line 494, in get_connection
    self.open_connection(
  File "C:\Users\Jithin Jose\OneDrive - NAIT\BAITS\NETW3100\NETW3100\Lib\site-packages\nornir\core\inventory.py", line 546, in open_connection
    conn_obj.open(
  File "C:\Users\Jithin Jose\OneDrive - NAIT\BAITS\NETW3100\NETW3100\Lib\site-packages\nornir_netmiko\connections\netmiko.py", line 59, in open
    connection = ConnectHandler(**parameters)
                 ^^^^^^^^^^^^^^^^^^^^^^^^^^^^
  File "C:\Users\Jithin Jose\OneDrive - NAIT\BAITS\NETW3100\NETW3100\Lib\site-packages\netmiko\ssh_dispatcher.py", line 365, in ConnectHandler
    return ConnectionClass(*args, **kwargs)
           ^^^^^^^^^^^^^^^^^^^^^^^^^^^^^^^^
  File "C:\Users\Jithin Jose\OneDrive - NAIT\BAITS\NETW3100\NETW3100\Lib\site-packages\netmiko\base_connection.py", line 439, in __init__
    self._open()
  File "C:\Users\Jithin Jose\OneDrive - NAIT\BAITS\NETW3100\NETW3100\Lib\site-packages\netmiko\base_connection.py", line 444, in _open
    self.establish_connection()
  File "C:\Users\Jithin Jose\OneDrive - NAIT\BAITS\NETW3100\NETW3100\Lib\site-packages\netmiko\base_connection.py", line 1068, in establish_connection
    raise NetmikoTimeoutException(msg)
netmiko.exceptions.NetmikoTimeoutException: TCP connection to device failed.

Common causes of this problem are:
1. Incorrect hostname or IP address.
2. Wrong TCP port.
3. Intermediate firewall blocking access.

Device settings: cisco_ios 192.168.3.6:22



2023-11-21 17:29:44,516 - nornir.core.task -    ERROR -      start() - Host 'R5': task 'netmiko_send_command' failed with traceback:
Traceback (most recent call last):
  File "C:\Users\Jithin Jose\OneDrive - NAIT\BAITS\NETW3100\NETW3100\Lib\site-packages\netmiko\base_connection.py", line 1046, in establish_connection
    self.remote_conn_pre.connect(**ssh_connect_params)
  File "C:\Users\Jithin Jose\OneDrive - NAIT\BAITS\NETW3100\NETW3100\Lib\site-packages\paramiko\client.py", line 386, in connect
    sock.connect(addr)
TimeoutError: timed out

During handling of the above exception, another exception occurred:

Traceback (most recent call last):
  File "C:\Users\Jithin Jose\OneDrive - NAIT\BAITS\NETW3100\NETW3100\Lib\site-packages\nornir\core\task.py", line 99, in start
    r = self.task(self, **self.params)
        ^^^^^^^^^^^^^^^^^^^^^^^^^^^^^^
  File "C:\Users\Jithin Jose\OneDrive - NAIT\BAITS\NETW3100\NETW3100\Lib\site-packages\nornir_netmiko\tasks\netmiko_send_command.py", line 26, in netmiko_send_command
    net_connect = task.host.get_connection(CONNECTION_NAME, task.nornir.config)
                  ^^^^^^^^^^^^^^^^^^^^^^^^^^^^^^^^^^^^^^^^^^^^^^^^^^^^^^^^^^^^^
  File "C:\Users\Jithin Jose\OneDrive - NAIT\BAITS\NETW3100\NETW3100\Lib\site-packages\nornir\core\inventory.py", line 494, in get_connection
    self.open_connection(
  File "C:\Users\Jithin Jose\OneDrive - NAIT\BAITS\NETW3100\NETW3100\Lib\site-packages\nornir\core\inventory.py", line 546, in open_connection
    conn_obj.open(
  File "C:\Users\Jithin Jose\OneDrive - NAIT\BAITS\NETW3100\NETW3100\Lib\site-packages\nornir_netmiko\connections\netmiko.py", line 59, in open
    connection = ConnectHandler(**parameters)
                 ^^^^^^^^^^^^^^^^^^^^^^^^^^^^
  File "C:\Users\Jithin Jose\OneDrive - NAIT\BAITS\NETW3100\NETW3100\Lib\site-packages\netmiko\ssh_dispatcher.py", line 365, in ConnectHandler
    return ConnectionClass(*args, **kwargs)
           ^^^^^^^^^^^^^^^^^^^^^^^^^^^^^^^^
  File "C:\Users\Jithin Jose\OneDrive - NAIT\BAITS\NETW3100\NETW3100\Lib\site-packages\netmiko\base_connection.py", line 439, in __init__
    self._open()
  File "C:\Users\Jithin Jose\OneDrive - NAIT\BAITS\NETW3100\NETW3100\Lib\site-packages\netmiko\base_connection.py", line 444, in _open
    self.establish_connection()
  File "C:\Users\Jithin Jose\OneDrive - NAIT\BAITS\NETW3100\NETW3100\Lib\site-packages\netmiko\base_connection.py", line 1068, in establish_connection
    raise NetmikoTimeoutException(msg)
netmiko.exceptions.NetmikoTimeoutException: TCP connection to device failed.

Common causes of this problem are:
1. Incorrect hostname or IP address.
2. Wrong TCP port.
3. Intermediate firewall blocking access.

Device settings: cisco_ios 192.168.3.5:22



2023-11-21 17:29:44,516 - nornir.core.task -    ERROR -      start() - Host 'R4': task 'netmiko_send_command' failed with traceback:
Traceback (most recent call last):
  File "C:\Users\Jithin Jose\OneDrive - NAIT\BAITS\NETW3100\NETW3100\Lib\site-packages\netmiko\base_connection.py", line 1046, in establish_connection
    self.remote_conn_pre.connect(**ssh_connect_params)
  File "C:\Users\Jithin Jose\OneDrive - NAIT\BAITS\NETW3100\NETW3100\Lib\site-packages\paramiko\client.py", line 386, in connect
    sock.connect(addr)
TimeoutError: timed out

During handling of the above exception, another exception occurred:

Traceback (most recent call last):
  File "C:\Users\Jithin Jose\OneDrive - NAIT\BAITS\NETW3100\NETW3100\Lib\site-packages\nornir\core\task.py", line 99, in start
    r = self.task(self, **self.params)
        ^^^^^^^^^^^^^^^^^^^^^^^^^^^^^^
  File "C:\Users\Jithin Jose\OneDrive - NAIT\BAITS\NETW3100\NETW3100\Lib\site-packages\nornir_netmiko\tasks\netmiko_send_command.py", line 26, in netmiko_send_command
    net_connect = task.host.get_connection(CONNECTION_NAME, task.nornir.config)
                  ^^^^^^^^^^^^^^^^^^^^^^^^^^^^^^^^^^^^^^^^^^^^^^^^^^^^^^^^^^^^^
  File "C:\Users\Jithin Jose\OneDrive - NAIT\BAITS\NETW3100\NETW3100\Lib\site-packages\nornir\core\inventory.py", line 494, in get_connection
    self.open_connection(
  File "C:\Users\Jithin Jose\OneDrive - NAIT\BAITS\NETW3100\NETW3100\Lib\site-packages\nornir\core\inventory.py", line 546, in open_connection
    conn_obj.open(
  File "C:\Users\Jithin Jose\OneDrive - NAIT\BAITS\NETW3100\NETW3100\Lib\site-packages\nornir_netmiko\connections\netmiko.py", line 59, in open
    connection = ConnectHandler(**parameters)
                 ^^^^^^^^^^^^^^^^^^^^^^^^^^^^
  File "C:\Users\Jithin Jose\OneDrive - NAIT\BAITS\NETW3100\NETW3100\Lib\site-packages\netmiko\ssh_dispatcher.py", line 365, in ConnectHandler
    return ConnectionClass(*args, **kwargs)
           ^^^^^^^^^^^^^^^^^^^^^^^^^^^^^^^^
  File "C:\Users\Jithin Jose\OneDrive - NAIT\BAITS\NETW3100\NETW3100\Lib\site-packages\netmiko\base_connection.py", line 439, in __init__
    self._open()
  File "C:\Users\Jithin Jose\OneDrive - NAIT\BAITS\NETW3100\NETW3100\Lib\site-packages\netmiko\base_connection.py", line 444, in _open
    self.establish_connection()
  File "C:\Users\Jithin Jose\OneDrive - NAIT\BAITS\NETW3100\NETW3100\Lib\site-packages\netmiko\base_connection.py", line 1068, in establish_connection
    raise NetmikoTimeoutException(msg)
netmiko.exceptions.NetmikoTimeoutException: TCP connection to device failed.

Common causes of this problem are:
1. Incorrect hostname or IP address.
2. Wrong TCP port.
3. Intermediate firewall blocking access.

Device settings: cisco_ios 192.168.3.4:22



2023-11-21 17:31:20,213 -  nornir.core -     INFO -        run() - Running task 'netmiko_send_command' with args {'command_string': 'Show ip int br', 'use_textfsm': True} on 10 hosts
2023-11-21 17:31:30,244 - nornir.core.task -    ERROR -      start() - Host 'SW2': task 'netmiko_send_command' failed with traceback:
Traceback (most recent call last):
  File "C:\Users\Jithin Jose\OneDrive - NAIT\BAITS\NETW3100\NETW3100\Lib\site-packages\netmiko\base_connection.py", line 1046, in establish_connection
    self.remote_conn_pre.connect(**ssh_connect_params)
  File "C:\Users\Jithin Jose\OneDrive - NAIT\BAITS\NETW3100\NETW3100\Lib\site-packages\paramiko\client.py", line 386, in connect
    sock.connect(addr)
TimeoutError: timed out

During handling of the above exception, another exception occurred:

Traceback (most recent call last):
  File "C:\Users\Jithin Jose\OneDrive - NAIT\BAITS\NETW3100\NETW3100\Lib\site-packages\nornir\core\task.py", line 99, in start
    r = self.task(self, **self.params)
        ^^^^^^^^^^^^^^^^^^^^^^^^^^^^^^
  File "C:\Users\Jithin Jose\OneDrive - NAIT\BAITS\NETW3100\NETW3100\Lib\site-packages\nornir_netmiko\tasks\netmiko_send_command.py", line 26, in netmiko_send_command
    net_connect = task.host.get_connection(CONNECTION_NAME, task.nornir.config)
                  ^^^^^^^^^^^^^^^^^^^^^^^^^^^^^^^^^^^^^^^^^^^^^^^^^^^^^^^^^^^^^
  File "C:\Users\Jithin Jose\OneDrive - NAIT\BAITS\NETW3100\NETW3100\Lib\site-packages\nornir\core\inventory.py", line 494, in get_connection
    self.open_connection(
  File "C:\Users\Jithin Jose\OneDrive - NAIT\BAITS\NETW3100\NETW3100\Lib\site-packages\nornir\core\inventory.py", line 546, in open_connection
    conn_obj.open(
  File "C:\Users\Jithin Jose\OneDrive - NAIT\BAITS\NETW3100\NETW3100\Lib\site-packages\nornir_netmiko\connections\netmiko.py", line 59, in open
    connection = ConnectHandler(**parameters)
                 ^^^^^^^^^^^^^^^^^^^^^^^^^^^^
  File "C:\Users\Jithin Jose\OneDrive - NAIT\BAITS\NETW3100\NETW3100\Lib\site-packages\netmiko\ssh_dispatcher.py", line 365, in ConnectHandler
    return ConnectionClass(*args, **kwargs)
           ^^^^^^^^^^^^^^^^^^^^^^^^^^^^^^^^
  File "C:\Users\Jithin Jose\OneDrive - NAIT\BAITS\NETW3100\NETW3100\Lib\site-packages\netmiko\base_connection.py", line 439, in __init__
    self._open()
  File "C:\Users\Jithin Jose\OneDrive - NAIT\BAITS\NETW3100\NETW3100\Lib\site-packages\netmiko\base_connection.py", line 444, in _open
    self.establish_connection()
  File "C:\Users\Jithin Jose\OneDrive - NAIT\BAITS\NETW3100\NETW3100\Lib\site-packages\netmiko\base_connection.py", line 1068, in establish_connection
    raise NetmikoTimeoutException(msg)
netmiko.exceptions.NetmikoTimeoutException: TCP connection to device failed.

Common causes of this problem are:
1. Incorrect hostname or IP address.
2. Wrong TCP port.
3. Intermediate firewall blocking access.

Device settings: cisco_ios 192.168.3.12:22



2023-11-21 17:31:30,244 - nornir.core.task -    ERROR -      start() - Host 'R4': task 'netmiko_send_command' failed with traceback:
Traceback (most recent call last):
  File "C:\Users\Jithin Jose\OneDrive - NAIT\BAITS\NETW3100\NETW3100\Lib\site-packages\netmiko\base_connection.py", line 1046, in establish_connection
    self.remote_conn_pre.connect(**ssh_connect_params)
  File "C:\Users\Jithin Jose\OneDrive - NAIT\BAITS\NETW3100\NETW3100\Lib\site-packages\paramiko\client.py", line 386, in connect
    sock.connect(addr)
TimeoutError: timed out

During handling of the above exception, another exception occurred:

Traceback (most recent call last):
  File "C:\Users\Jithin Jose\OneDrive - NAIT\BAITS\NETW3100\NETW3100\Lib\site-packages\nornir\core\task.py", line 99, in start
    r = self.task(self, **self.params)
        ^^^^^^^^^^^^^^^^^^^^^^^^^^^^^^
  File "C:\Users\Jithin Jose\OneDrive - NAIT\BAITS\NETW3100\NETW3100\Lib\site-packages\nornir_netmiko\tasks\netmiko_send_command.py", line 26, in netmiko_send_command
    net_connect = task.host.get_connection(CONNECTION_NAME, task.nornir.config)
                  ^^^^^^^^^^^^^^^^^^^^^^^^^^^^^^^^^^^^^^^^^^^^^^^^^^^^^^^^^^^^^
  File "C:\Users\Jithin Jose\OneDrive - NAIT\BAITS\NETW3100\NETW3100\Lib\site-packages\nornir\core\inventory.py", line 494, in get_connection
    self.open_connection(
  File "C:\Users\Jithin Jose\OneDrive - NAIT\BAITS\NETW3100\NETW3100\Lib\site-packages\nornir\core\inventory.py", line 546, in open_connection
    conn_obj.open(
  File "C:\Users\Jithin Jose\OneDrive - NAIT\BAITS\NETW3100\NETW3100\Lib\site-packages\nornir_netmiko\connections\netmiko.py", line 59, in open
    connection = ConnectHandler(**parameters)
                 ^^^^^^^^^^^^^^^^^^^^^^^^^^^^
  File "C:\Users\Jithin Jose\OneDrive - NAIT\BAITS\NETW3100\NETW3100\Lib\site-packages\netmiko\ssh_dispatcher.py", line 365, in ConnectHandler
    return ConnectionClass(*args, **kwargs)
           ^^^^^^^^^^^^^^^^^^^^^^^^^^^^^^^^
  File "C:\Users\Jithin Jose\OneDrive - NAIT\BAITS\NETW3100\NETW3100\Lib\site-packages\netmiko\base_connection.py", line 439, in __init__
    self._open()
  File "C:\Users\Jithin Jose\OneDrive - NAIT\BAITS\NETW3100\NETW3100\Lib\site-packages\netmiko\base_connection.py", line 444, in _open
    self.establish_connection()
  File "C:\Users\Jithin Jose\OneDrive - NAIT\BAITS\NETW3100\NETW3100\Lib\site-packages\netmiko\base_connection.py", line 1068, in establish_connection
    raise NetmikoTimeoutException(msg)
netmiko.exceptions.NetmikoTimeoutException: TCP connection to device failed.

Common causes of this problem are:
1. Incorrect hostname or IP address.
2. Wrong TCP port.
3. Intermediate firewall blocking access.

Device settings: cisco_ios 192.168.3.4:22



2023-11-21 17:31:30,244 - nornir.core.task -    ERROR -      start() - Host 'R5': task 'netmiko_send_command' failed with traceback:
Traceback (most recent call last):
  File "C:\Users\Jithin Jose\OneDrive - NAIT\BAITS\NETW3100\NETW3100\Lib\site-packages\netmiko\base_connection.py", line 1046, in establish_connection
    self.remote_conn_pre.connect(**ssh_connect_params)
  File "C:\Users\Jithin Jose\OneDrive - NAIT\BAITS\NETW3100\NETW3100\Lib\site-packages\paramiko\client.py", line 386, in connect
    sock.connect(addr)
TimeoutError: timed out

During handling of the above exception, another exception occurred:

Traceback (most recent call last):
  File "C:\Users\Jithin Jose\OneDrive - NAIT\BAITS\NETW3100\NETW3100\Lib\site-packages\nornir\core\task.py", line 99, in start
    r = self.task(self, **self.params)
        ^^^^^^^^^^^^^^^^^^^^^^^^^^^^^^
  File "C:\Users\Jithin Jose\OneDrive - NAIT\BAITS\NETW3100\NETW3100\Lib\site-packages\nornir_netmiko\tasks\netmiko_send_command.py", line 26, in netmiko_send_command
    net_connect = task.host.get_connection(CONNECTION_NAME, task.nornir.config)
                  ^^^^^^^^^^^^^^^^^^^^^^^^^^^^^^^^^^^^^^^^^^^^^^^^^^^^^^^^^^^^^
  File "C:\Users\Jithin Jose\OneDrive - NAIT\BAITS\NETW3100\NETW3100\Lib\site-packages\nornir\core\inventory.py", line 494, in get_connection
    self.open_connection(
  File "C:\Users\Jithin Jose\OneDrive - NAIT\BAITS\NETW3100\NETW3100\Lib\site-packages\nornir\core\inventory.py", line 546, in open_connection
    conn_obj.open(
  File "C:\Users\Jithin Jose\OneDrive - NAIT\BAITS\NETW3100\NETW3100\Lib\site-packages\nornir_netmiko\connections\netmiko.py", line 59, in open
    connection = ConnectHandler(**parameters)
                 ^^^^^^^^^^^^^^^^^^^^^^^^^^^^
  File "C:\Users\Jithin Jose\OneDrive - NAIT\BAITS\NETW3100\NETW3100\Lib\site-packages\netmiko\ssh_dispatcher.py", line 365, in ConnectHandler
    return ConnectionClass(*args, **kwargs)
           ^^^^^^^^^^^^^^^^^^^^^^^^^^^^^^^^
  File "C:\Users\Jithin Jose\OneDrive - NAIT\BAITS\NETW3100\NETW3100\Lib\site-packages\netmiko\base_connection.py", line 439, in __init__
    self._open()
  File "C:\Users\Jithin Jose\OneDrive - NAIT\BAITS\NETW3100\NETW3100\Lib\site-packages\netmiko\base_connection.py", line 444, in _open
    self.establish_connection()
  File "C:\Users\Jithin Jose\OneDrive - NAIT\BAITS\NETW3100\NETW3100\Lib\site-packages\netmiko\base_connection.py", line 1068, in establish_connection
    raise NetmikoTimeoutException(msg)
netmiko.exceptions.NetmikoTimeoutException: TCP connection to device failed.

Common causes of this problem are:
1. Incorrect hostname or IP address.
2. Wrong TCP port.
3. Intermediate firewall blocking access.

Device settings: cisco_ios 192.168.3.5:22



2023-11-21 17:31:30,244 - nornir.core.task -    ERROR -      start() - Host 'R6': task 'netmiko_send_command' failed with traceback:
Traceback (most recent call last):
  File "C:\Users\Jithin Jose\OneDrive - NAIT\BAITS\NETW3100\NETW3100\Lib\site-packages\netmiko\base_connection.py", line 1046, in establish_connection
    self.remote_conn_pre.connect(**ssh_connect_params)
  File "C:\Users\Jithin Jose\OneDrive - NAIT\BAITS\NETW3100\NETW3100\Lib\site-packages\paramiko\client.py", line 386, in connect
    sock.connect(addr)
TimeoutError: timed out

During handling of the above exception, another exception occurred:

Traceback (most recent call last):
  File "C:\Users\Jithin Jose\OneDrive - NAIT\BAITS\NETW3100\NETW3100\Lib\site-packages\nornir\core\task.py", line 99, in start
    r = self.task(self, **self.params)
        ^^^^^^^^^^^^^^^^^^^^^^^^^^^^^^
  File "C:\Users\Jithin Jose\OneDrive - NAIT\BAITS\NETW3100\NETW3100\Lib\site-packages\nornir_netmiko\tasks\netmiko_send_command.py", line 26, in netmiko_send_command
    net_connect = task.host.get_connection(CONNECTION_NAME, task.nornir.config)
                  ^^^^^^^^^^^^^^^^^^^^^^^^^^^^^^^^^^^^^^^^^^^^^^^^^^^^^^^^^^^^^
  File "C:\Users\Jithin Jose\OneDrive - NAIT\BAITS\NETW3100\NETW3100\Lib\site-packages\nornir\core\inventory.py", line 494, in get_connection
    self.open_connection(
  File "C:\Users\Jithin Jose\OneDrive - NAIT\BAITS\NETW3100\NETW3100\Lib\site-packages\nornir\core\inventory.py", line 546, in open_connection
    conn_obj.open(
  File "C:\Users\Jithin Jose\OneDrive - NAIT\BAITS\NETW3100\NETW3100\Lib\site-packages\nornir_netmiko\connections\netmiko.py", line 59, in open
    connection = ConnectHandler(**parameters)
                 ^^^^^^^^^^^^^^^^^^^^^^^^^^^^
  File "C:\Users\Jithin Jose\OneDrive - NAIT\BAITS\NETW3100\NETW3100\Lib\site-packages\netmiko\ssh_dispatcher.py", line 365, in ConnectHandler
    return ConnectionClass(*args, **kwargs)
           ^^^^^^^^^^^^^^^^^^^^^^^^^^^^^^^^
  File "C:\Users\Jithin Jose\OneDrive - NAIT\BAITS\NETW3100\NETW3100\Lib\site-packages\netmiko\base_connection.py", line 439, in __init__
    self._open()
  File "C:\Users\Jithin Jose\OneDrive - NAIT\BAITS\NETW3100\NETW3100\Lib\site-packages\netmiko\base_connection.py", line 444, in _open
    self.establish_connection()
  File "C:\Users\Jithin Jose\OneDrive - NAIT\BAITS\NETW3100\NETW3100\Lib\site-packages\netmiko\base_connection.py", line 1068, in establish_connection
    raise NetmikoTimeoutException(msg)
netmiko.exceptions.NetmikoTimeoutException: TCP connection to device failed.

Common causes of this problem are:
1. Incorrect hostname or IP address.
2. Wrong TCP port.
3. Intermediate firewall blocking access.

Device settings: cisco_ios 192.168.3.6:22



2023-11-23 09:55:12,168 -  nornir.core -     INFO -        run() - Running task 'netmiko_send_command' with args {'command_string': 'Show ip int br', 'use_textfsm': True} on 10 hosts
2023-11-23 09:59:27,982 -  nornir.core -     INFO -        run() - Running task 'netmiko_send_command' with args {'command_string': 'Show ip int br', 'use_textfsm': True} on 10 hosts
2023-11-23 10:01:09,744 -  nornir.core -     INFO -        run() - Running task 'netmiko_send_command' with args {'command_string': 'Show ip int br', 'use_textfsm': True} on 10 hosts
2023-11-23 10:01:58,250 -  nornir.core -     INFO -        run() - Running task 'netmiko_send_command' with args {'command_string': 'Show ip int br', 'use_textfsm': True} on 10 hosts
2023-11-23 10:02:31,327 -  nornir.core -     INFO -        run() - Running task 'netmiko_send_command' with args {'command_string': 'Show ip int br', 'use_textfsm': True} on 10 hosts
2023-11-23 10:04:03,108 -  nornir.core -     INFO -        run() - Running task 'netmiko_send_command' with args {'command_string': 'Show ip int br', 'use_textfsm': True} on 10 hosts
2023-11-23 10:06:18,101 -  nornir.core -     INFO -        run() - Running task 'netmiko_send_command' with args {'command_string': 'Show ip int br', 'use_textfsm': True} on 10 hosts
2023-11-23 10:09:02,351 -  nornir.core -     INFO -        run() - Running task 'netmiko_send_command' with args {'command_string': 'Show ip int br', 'use_textfsm': True} on 10 hosts
2023-11-23 10:10:40,341 -  nornir.core -     INFO -        run() - Running task 'netmiko_send_command' with args {'command_string': 'Show ip int br', 'use_textfsm': True} on 10 hosts
2023-11-23 10:14:52,957 -  nornir.core -     INFO -        run() - Running task 'netmiko_send_command' with args {'command_string': 'Show ip int br', 'use_textfsm': True} on 10 hosts
2023-11-23 10:31:55,547 -  nornir.core -     INFO -        run() - Running task 'netmiko_send_command' with args {'command_string': 'Show ip int br', 'use_textfsm': True} on 10 hosts
2023-11-23 10:33:53,136 -  nornir.core -     INFO -        run() - Running task 'netmiko_send_command' with args {'command_string': 'Show ip int br', 'use_textfsm': True} on 10 hosts
2023-11-23 10:34:06,673 -  nornir.core -     INFO -        run() - Running task 'netmiko_send_command' with args {'command_string': 'Show ip int br', 'use_textfsm': True} on 10 hosts
2023-11-23 10:40:03,916 -  nornir.core -     INFO -        run() - Running task 'netmiko_send_command' with args {'command_string': 'Show ip int br', 'use_textfsm': True} on 10 hosts
2023-11-23 10:42:28,790 -  nornir.core -     INFO -        run() - Running task 'netmiko_send_command' with args {'command_string': 'Show ip int br', 'use_textfsm': True} on 10 hosts
2023-11-24 10:40:29,334 -  nornir.core -     INFO -        run() - Running task 'netmiko_send_command' with args {'command_string': 'Show ip int br', 'use_textfsm': True} on 10 hosts
2023-11-24 10:40:39,378 - nornir.core.task -    ERROR -      start() - Host 'SW3': task 'netmiko_send_command' failed with traceback:
Traceback (most recent call last):
  File "C:\Users\Jithin Jose\OneDrive - NAIT\BAITS\NETW3100\NETW3100\Lib\site-packages\netmiko\base_connection.py", line 1137, in establish_connection
    self.remote_conn_pre.connect(**ssh_connect_params)
  File "C:\Users\Jithin Jose\OneDrive - NAIT\BAITS\NETW3100\NETW3100\Lib\site-packages\paramiko\client.py", line 386, in connect
    sock.connect(addr)
TimeoutError: timed out

During handling of the above exception, another exception occurred:

Traceback (most recent call last):
  File "C:\Users\Jithin Jose\OneDrive - NAIT\BAITS\NETW3100\NETW3100\Lib\site-packages\nornir\core\task.py", line 99, in start
    r = self.task(self, **self.params)
        ^^^^^^^^^^^^^^^^^^^^^^^^^^^^^^
  File "C:\Users\Jithin Jose\OneDrive - NAIT\BAITS\NETW3100\NETW3100\Lib\site-packages\nornir_netmiko\tasks\netmiko_send_command.py", line 26, in netmiko_send_command
    net_connect = task.host.get_connection(CONNECTION_NAME, task.nornir.config)
                  ^^^^^^^^^^^^^^^^^^^^^^^^^^^^^^^^^^^^^^^^^^^^^^^^^^^^^^^^^^^^^
  File "C:\Users\Jithin Jose\OneDrive - NAIT\BAITS\NETW3100\NETW3100\Lib\site-packages\nornir\core\inventory.py", line 494, in get_connection
    self.open_connection(
  File "C:\Users\Jithin Jose\OneDrive - NAIT\BAITS\NETW3100\NETW3100\Lib\site-packages\nornir\core\inventory.py", line 546, in open_connection
    conn_obj.open(
  File "C:\Users\Jithin Jose\OneDrive - NAIT\BAITS\NETW3100\NETW3100\Lib\site-packages\nornir_netmiko\connections\netmiko.py", line 59, in open
    connection = ConnectHandler(**parameters)
                 ^^^^^^^^^^^^^^^^^^^^^^^^^^^^
  File "C:\Users\Jithin Jose\OneDrive - NAIT\BAITS\NETW3100\NETW3100\Lib\site-packages\netmiko\ssh_dispatcher.py", line 399, in ConnectHandler
    return ConnectionClass(*args, **kwargs)
           ^^^^^^^^^^^^^^^^^^^^^^^^^^^^^^^^
  File "C:\Users\Jithin Jose\OneDrive - NAIT\BAITS\NETW3100\NETW3100\Lib\site-packages\netmiko\base_connection.py", line 488, in __init__
    self._open()
  File "C:\Users\Jithin Jose\OneDrive - NAIT\BAITS\NETW3100\NETW3100\Lib\site-packages\netmiko\base_connection.py", line 493, in _open
    self.establish_connection()
  File "C:\Users\Jithin Jose\OneDrive - NAIT\BAITS\NETW3100\NETW3100\Lib\site-packages\netmiko\base_connection.py", line 1159, in establish_connection
    raise NetmikoTimeoutException(msg)
netmiko.exceptions.NetmikoTimeoutException: TCP connection to device failed.

Common causes of this problem are:
1. Incorrect hostname or IP address.
2. Wrong TCP port.
3. Intermediate firewall blocking access.

Device settings: cisco_ios 192.168.3.13:22



2023-11-24 10:40:39,378 - nornir.core.task -    ERROR -      start() - Host 'R1': task 'netmiko_send_command' failed with traceback:
Traceback (most recent call last):
  File "C:\Users\Jithin Jose\OneDrive - NAIT\BAITS\NETW3100\NETW3100\Lib\site-packages\netmiko\base_connection.py", line 1137, in establish_connection
    self.remote_conn_pre.connect(**ssh_connect_params)
  File "C:\Users\Jithin Jose\OneDrive - NAIT\BAITS\NETW3100\NETW3100\Lib\site-packages\paramiko\client.py", line 386, in connect
    sock.connect(addr)
TimeoutError: timed out

During handling of the above exception, another exception occurred:

Traceback (most recent call last):
  File "C:\Users\Jithin Jose\OneDrive - NAIT\BAITS\NETW3100\NETW3100\Lib\site-packages\nornir\core\task.py", line 99, in start
    r = self.task(self, **self.params)
        ^^^^^^^^^^^^^^^^^^^^^^^^^^^^^^
  File "C:\Users\Jithin Jose\OneDrive - NAIT\BAITS\NETW3100\NETW3100\Lib\site-packages\nornir_netmiko\tasks\netmiko_send_command.py", line 26, in netmiko_send_command
    net_connect = task.host.get_connection(CONNECTION_NAME, task.nornir.config)
                  ^^^^^^^^^^^^^^^^^^^^^^^^^^^^^^^^^^^^^^^^^^^^^^^^^^^^^^^^^^^^^
  File "C:\Users\Jithin Jose\OneDrive - NAIT\BAITS\NETW3100\NETW3100\Lib\site-packages\nornir\core\inventory.py", line 494, in get_connection
    self.open_connection(
  File "C:\Users\Jithin Jose\OneDrive - NAIT\BAITS\NETW3100\NETW3100\Lib\site-packages\nornir\core\inventory.py", line 546, in open_connection
    conn_obj.open(
  File "C:\Users\Jithin Jose\OneDrive - NAIT\BAITS\NETW3100\NETW3100\Lib\site-packages\nornir_netmiko\connections\netmiko.py", line 59, in open
    connection = ConnectHandler(**parameters)
                 ^^^^^^^^^^^^^^^^^^^^^^^^^^^^
  File "C:\Users\Jithin Jose\OneDrive - NAIT\BAITS\NETW3100\NETW3100\Lib\site-packages\netmiko\ssh_dispatcher.py", line 399, in ConnectHandler
    return ConnectionClass(*args, **kwargs)
           ^^^^^^^^^^^^^^^^^^^^^^^^^^^^^^^^
  File "C:\Users\Jithin Jose\OneDrive - NAIT\BAITS\NETW3100\NETW3100\Lib\site-packages\netmiko\base_connection.py", line 488, in __init__
    self._open()
  File "C:\Users\Jithin Jose\OneDrive - NAIT\BAITS\NETW3100\NETW3100\Lib\site-packages\netmiko\base_connection.py", line 493, in _open
    self.establish_connection()
  File "C:\Users\Jithin Jose\OneDrive - NAIT\BAITS\NETW3100\NETW3100\Lib\site-packages\netmiko\base_connection.py", line 1159, in establish_connection
    raise NetmikoTimeoutException(msg)
netmiko.exceptions.NetmikoTimeoutException: TCP connection to device failed.

Common causes of this problem are:
1. Incorrect hostname or IP address.
2. Wrong TCP port.
3. Intermediate firewall blocking access.

Device settings: cisco_ios 192.168.3.1:22



2023-11-24 10:40:39,378 - nornir.core.task -    ERROR -      start() - Host 'R5': task 'netmiko_send_command' failed with traceback:
Traceback (most recent call last):
  File "C:\Users\Jithin Jose\OneDrive - NAIT\BAITS\NETW3100\NETW3100\Lib\site-packages\netmiko\base_connection.py", line 1137, in establish_connection
    self.remote_conn_pre.connect(**ssh_connect_params)
  File "C:\Users\Jithin Jose\OneDrive - NAIT\BAITS\NETW3100\NETW3100\Lib\site-packages\paramiko\client.py", line 386, in connect
    sock.connect(addr)
TimeoutError: timed out

During handling of the above exception, another exception occurred:

Traceback (most recent call last):
  File "C:\Users\Jithin Jose\OneDrive - NAIT\BAITS\NETW3100\NETW3100\Lib\site-packages\nornir\core\task.py", line 99, in start
    r = self.task(self, **self.params)
        ^^^^^^^^^^^^^^^^^^^^^^^^^^^^^^
  File "C:\Users\Jithin Jose\OneDrive - NAIT\BAITS\NETW3100\NETW3100\Lib\site-packages\nornir_netmiko\tasks\netmiko_send_command.py", line 26, in netmiko_send_command
    net_connect = task.host.get_connection(CONNECTION_NAME, task.nornir.config)
                  ^^^^^^^^^^^^^^^^^^^^^^^^^^^^^^^^^^^^^^^^^^^^^^^^^^^^^^^^^^^^^
  File "C:\Users\Jithin Jose\OneDrive - NAIT\BAITS\NETW3100\NETW3100\Lib\site-packages\nornir\core\inventory.py", line 494, in get_connection
    self.open_connection(
  File "C:\Users\Jithin Jose\OneDrive - NAIT\BAITS\NETW3100\NETW3100\Lib\site-packages\nornir\core\inventory.py", line 546, in open_connection
    conn_obj.open(
  File "C:\Users\Jithin Jose\OneDrive - NAIT\BAITS\NETW3100\NETW3100\Lib\site-packages\nornir_netmiko\connections\netmiko.py", line 59, in open
    connection = ConnectHandler(**parameters)
                 ^^^^^^^^^^^^^^^^^^^^^^^^^^^^
  File "C:\Users\Jithin Jose\OneDrive - NAIT\BAITS\NETW3100\NETW3100\Lib\site-packages\netmiko\ssh_dispatcher.py", line 399, in ConnectHandler
    return ConnectionClass(*args, **kwargs)
           ^^^^^^^^^^^^^^^^^^^^^^^^^^^^^^^^
  File "C:\Users\Jithin Jose\OneDrive - NAIT\BAITS\NETW3100\NETW3100\Lib\site-packages\netmiko\base_connection.py", line 488, in __init__
    self._open()
  File "C:\Users\Jithin Jose\OneDrive - NAIT\BAITS\NETW3100\NETW3100\Lib\site-packages\netmiko\base_connection.py", line 493, in _open
    self.establish_connection()
  File "C:\Users\Jithin Jose\OneDrive - NAIT\BAITS\NETW3100\NETW3100\Lib\site-packages\netmiko\base_connection.py", line 1159, in establish_connection
    raise NetmikoTimeoutException(msg)
netmiko.exceptions.NetmikoTimeoutException: TCP connection to device failed.

Common causes of this problem are:
1. Incorrect hostname or IP address.
2. Wrong TCP port.
3. Intermediate firewall blocking access.

Device settings: cisco_ios 192.168.3.5:22



2023-11-24 10:40:39,378 - nornir.core.task -    ERROR -      start() - Host 'R6': task 'netmiko_send_command' failed with traceback:
Traceback (most recent call last):
  File "C:\Users\Jithin Jose\OneDrive - NAIT\BAITS\NETW3100\NETW3100\Lib\site-packages\netmiko\base_connection.py", line 1137, in establish_connection
    self.remote_conn_pre.connect(**ssh_connect_params)
  File "C:\Users\Jithin Jose\OneDrive - NAIT\BAITS\NETW3100\NETW3100\Lib\site-packages\paramiko\client.py", line 386, in connect
    sock.connect(addr)
TimeoutError: timed out

During handling of the above exception, another exception occurred:

Traceback (most recent call last):
  File "C:\Users\Jithin Jose\OneDrive - NAIT\BAITS\NETW3100\NETW3100\Lib\site-packages\nornir\core\task.py", line 99, in start
    r = self.task(self, **self.params)
        ^^^^^^^^^^^^^^^^^^^^^^^^^^^^^^
  File "C:\Users\Jithin Jose\OneDrive - NAIT\BAITS\NETW3100\NETW3100\Lib\site-packages\nornir_netmiko\tasks\netmiko_send_command.py", line 26, in netmiko_send_command
    net_connect = task.host.get_connection(CONNECTION_NAME, task.nornir.config)
                  ^^^^^^^^^^^^^^^^^^^^^^^^^^^^^^^^^^^^^^^^^^^^^^^^^^^^^^^^^^^^^
  File "C:\Users\Jithin Jose\OneDrive - NAIT\BAITS\NETW3100\NETW3100\Lib\site-packages\nornir\core\inventory.py", line 494, in get_connection
    self.open_connection(
  File "C:\Users\Jithin Jose\OneDrive - NAIT\BAITS\NETW3100\NETW3100\Lib\site-packages\nornir\core\inventory.py", line 546, in open_connection
    conn_obj.open(
  File "C:\Users\Jithin Jose\OneDrive - NAIT\BAITS\NETW3100\NETW3100\Lib\site-packages\nornir_netmiko\connections\netmiko.py", line 59, in open
    connection = ConnectHandler(**parameters)
                 ^^^^^^^^^^^^^^^^^^^^^^^^^^^^
  File "C:\Users\Jithin Jose\OneDrive - NAIT\BAITS\NETW3100\NETW3100\Lib\site-packages\netmiko\ssh_dispatcher.py", line 399, in ConnectHandler
    return ConnectionClass(*args, **kwargs)
           ^^^^^^^^^^^^^^^^^^^^^^^^^^^^^^^^
  File "C:\Users\Jithin Jose\OneDrive - NAIT\BAITS\NETW3100\NETW3100\Lib\site-packages\netmiko\base_connection.py", line 488, in __init__
    self._open()
  File "C:\Users\Jithin Jose\OneDrive - NAIT\BAITS\NETW3100\NETW3100\Lib\site-packages\netmiko\base_connection.py", line 493, in _open
    self.establish_connection()
  File "C:\Users\Jithin Jose\OneDrive - NAIT\BAITS\NETW3100\NETW3100\Lib\site-packages\netmiko\base_connection.py", line 1159, in establish_connection
    raise NetmikoTimeoutException(msg)
netmiko.exceptions.NetmikoTimeoutException: TCP connection to device failed.

Common causes of this problem are:
1. Incorrect hostname or IP address.
2. Wrong TCP port.
3. Intermediate firewall blocking access.

Device settings: cisco_ios 192.168.3.6:22



2023-11-24 10:40:39,378 - nornir.core.task -    ERROR -      start() - Host 'SW1': task 'netmiko_send_command' failed with traceback:
Traceback (most recent call last):
  File "C:\Users\Jithin Jose\OneDrive - NAIT\BAITS\NETW3100\NETW3100\Lib\site-packages\netmiko\base_connection.py", line 1137, in establish_connection
    self.remote_conn_pre.connect(**ssh_connect_params)
  File "C:\Users\Jithin Jose\OneDrive - NAIT\BAITS\NETW3100\NETW3100\Lib\site-packages\paramiko\client.py", line 386, in connect
    sock.connect(addr)
TimeoutError: timed out

During handling of the above exception, another exception occurred:

Traceback (most recent call last):
  File "C:\Users\Jithin Jose\OneDrive - NAIT\BAITS\NETW3100\NETW3100\Lib\site-packages\nornir\core\task.py", line 99, in start
    r = self.task(self, **self.params)
        ^^^^^^^^^^^^^^^^^^^^^^^^^^^^^^
  File "C:\Users\Jithin Jose\OneDrive - NAIT\BAITS\NETW3100\NETW3100\Lib\site-packages\nornir_netmiko\tasks\netmiko_send_command.py", line 26, in netmiko_send_command
    net_connect = task.host.get_connection(CONNECTION_NAME, task.nornir.config)
                  ^^^^^^^^^^^^^^^^^^^^^^^^^^^^^^^^^^^^^^^^^^^^^^^^^^^^^^^^^^^^^
  File "C:\Users\Jithin Jose\OneDrive - NAIT\BAITS\NETW3100\NETW3100\Lib\site-packages\nornir\core\inventory.py", line 494, in get_connection
    self.open_connection(
  File "C:\Users\Jithin Jose\OneDrive - NAIT\BAITS\NETW3100\NETW3100\Lib\site-packages\nornir\core\inventory.py", line 546, in open_connection
    conn_obj.open(
  File "C:\Users\Jithin Jose\OneDrive - NAIT\BAITS\NETW3100\NETW3100\Lib\site-packages\nornir_netmiko\connections\netmiko.py", line 59, in open
    connection = ConnectHandler(**parameters)
                 ^^^^^^^^^^^^^^^^^^^^^^^^^^^^
  File "C:\Users\Jithin Jose\OneDrive - NAIT\BAITS\NETW3100\NETW3100\Lib\site-packages\netmiko\ssh_dispatcher.py", line 399, in ConnectHandler
    return ConnectionClass(*args, **kwargs)
           ^^^^^^^^^^^^^^^^^^^^^^^^^^^^^^^^
  File "C:\Users\Jithin Jose\OneDrive - NAIT\BAITS\NETW3100\NETW3100\Lib\site-packages\netmiko\base_connection.py", line 488, in __init__
    self._open()
  File "C:\Users\Jithin Jose\OneDrive - NAIT\BAITS\NETW3100\NETW3100\Lib\site-packages\netmiko\base_connection.py", line 493, in _open
    self.establish_connection()
  File "C:\Users\Jithin Jose\OneDrive - NAIT\BAITS\NETW3100\NETW3100\Lib\site-packages\netmiko\base_connection.py", line 1159, in establish_connection
    raise NetmikoTimeoutException(msg)
netmiko.exceptions.NetmikoTimeoutException: TCP connection to device failed.

Common causes of this problem are:
1. Incorrect hostname or IP address.
2. Wrong TCP port.
3. Intermediate firewall blocking access.

Device settings: cisco_ios 192.168.3.11:22



2023-11-24 10:40:39,393 - nornir.core.task -    ERROR -      start() - Host 'SW4': task 'netmiko_send_command' failed with traceback:
Traceback (most recent call last):
  File "C:\Users\Jithin Jose\OneDrive - NAIT\BAITS\NETW3100\NETW3100\Lib\site-packages\netmiko\base_connection.py", line 1137, in establish_connection
    self.remote_conn_pre.connect(**ssh_connect_params)
  File "C:\Users\Jithin Jose\OneDrive - NAIT\BAITS\NETW3100\NETW3100\Lib\site-packages\paramiko\client.py", line 386, in connect
    sock.connect(addr)
TimeoutError: timed out

During handling of the above exception, another exception occurred:

Traceback (most recent call last):
  File "C:\Users\Jithin Jose\OneDrive - NAIT\BAITS\NETW3100\NETW3100\Lib\site-packages\nornir\core\task.py", line 99, in start
    r = self.task(self, **self.params)
        ^^^^^^^^^^^^^^^^^^^^^^^^^^^^^^
  File "C:\Users\Jithin Jose\OneDrive - NAIT\BAITS\NETW3100\NETW3100\Lib\site-packages\nornir_netmiko\tasks\netmiko_send_command.py", line 26, in netmiko_send_command
    net_connect = task.host.get_connection(CONNECTION_NAME, task.nornir.config)
                  ^^^^^^^^^^^^^^^^^^^^^^^^^^^^^^^^^^^^^^^^^^^^^^^^^^^^^^^^^^^^^
  File "C:\Users\Jithin Jose\OneDrive - NAIT\BAITS\NETW3100\NETW3100\Lib\site-packages\nornir\core\inventory.py", line 494, in get_connection
    self.open_connection(
  File "C:\Users\Jithin Jose\OneDrive - NAIT\BAITS\NETW3100\NETW3100\Lib\site-packages\nornir\core\inventory.py", line 546, in open_connection
    conn_obj.open(
  File "C:\Users\Jithin Jose\OneDrive - NAIT\BAITS\NETW3100\NETW3100\Lib\site-packages\nornir_netmiko\connections\netmiko.py", line 59, in open
    connection = ConnectHandler(**parameters)
                 ^^^^^^^^^^^^^^^^^^^^^^^^^^^^
  File "C:\Users\Jithin Jose\OneDrive - NAIT\BAITS\NETW3100\NETW3100\Lib\site-packages\netmiko\ssh_dispatcher.py", line 399, in ConnectHandler
    return ConnectionClass(*args, **kwargs)
           ^^^^^^^^^^^^^^^^^^^^^^^^^^^^^^^^
  File "C:\Users\Jithin Jose\OneDrive - NAIT\BAITS\NETW3100\NETW3100\Lib\site-packages\netmiko\base_connection.py", line 488, in __init__
    self._open()
  File "C:\Users\Jithin Jose\OneDrive - NAIT\BAITS\NETW3100\NETW3100\Lib\site-packages\netmiko\base_connection.py", line 493, in _open
    self.establish_connection()
  File "C:\Users\Jithin Jose\OneDrive - NAIT\BAITS\NETW3100\NETW3100\Lib\site-packages\netmiko\base_connection.py", line 1159, in establish_connection
    raise NetmikoTimeoutException(msg)
netmiko.exceptions.NetmikoTimeoutException: TCP connection to device failed.

Common causes of this problem are:
1. Incorrect hostname or IP address.
2. Wrong TCP port.
3. Intermediate firewall blocking access.

Device settings: cisco_ios 192.168.3.14:22



2023-11-24 10:40:39,393 - nornir.core.task -    ERROR -      start() - Host 'SW2': task 'netmiko_send_command' failed with traceback:
Traceback (most recent call last):
  File "C:\Users\Jithin Jose\OneDrive - NAIT\BAITS\NETW3100\NETW3100\Lib\site-packages\netmiko\base_connection.py", line 1137, in establish_connection
    self.remote_conn_pre.connect(**ssh_connect_params)
  File "C:\Users\Jithin Jose\OneDrive - NAIT\BAITS\NETW3100\NETW3100\Lib\site-packages\paramiko\client.py", line 386, in connect
    sock.connect(addr)
TimeoutError: timed out

During handling of the above exception, another exception occurred:

Traceback (most recent call last):
  File "C:\Users\Jithin Jose\OneDrive - NAIT\BAITS\NETW3100\NETW3100\Lib\site-packages\nornir\core\task.py", line 99, in start
    r = self.task(self, **self.params)
        ^^^^^^^^^^^^^^^^^^^^^^^^^^^^^^
  File "C:\Users\Jithin Jose\OneDrive - NAIT\BAITS\NETW3100\NETW3100\Lib\site-packages\nornir_netmiko\tasks\netmiko_send_command.py", line 26, in netmiko_send_command
    net_connect = task.host.get_connection(CONNECTION_NAME, task.nornir.config)
                  ^^^^^^^^^^^^^^^^^^^^^^^^^^^^^^^^^^^^^^^^^^^^^^^^^^^^^^^^^^^^^
  File "C:\Users\Jithin Jose\OneDrive - NAIT\BAITS\NETW3100\NETW3100\Lib\site-packages\nornir\core\inventory.py", line 494, in get_connection
    self.open_connection(
  File "C:\Users\Jithin Jose\OneDrive - NAIT\BAITS\NETW3100\NETW3100\Lib\site-packages\nornir\core\inventory.py", line 546, in open_connection
    conn_obj.open(
  File "C:\Users\Jithin Jose\OneDrive - NAIT\BAITS\NETW3100\NETW3100\Lib\site-packages\nornir_netmiko\connections\netmiko.py", line 59, in open
    connection = ConnectHandler(**parameters)
                 ^^^^^^^^^^^^^^^^^^^^^^^^^^^^
  File "C:\Users\Jithin Jose\OneDrive - NAIT\BAITS\NETW3100\NETW3100\Lib\site-packages\netmiko\ssh_dispatcher.py", line 399, in ConnectHandler
    return ConnectionClass(*args, **kwargs)
           ^^^^^^^^^^^^^^^^^^^^^^^^^^^^^^^^
  File "C:\Users\Jithin Jose\OneDrive - NAIT\BAITS\NETW3100\NETW3100\Lib\site-packages\netmiko\base_connection.py", line 488, in __init__
    self._open()
  File "C:\Users\Jithin Jose\OneDrive - NAIT\BAITS\NETW3100\NETW3100\Lib\site-packages\netmiko\base_connection.py", line 493, in _open
    self.establish_connection()
  File "C:\Users\Jithin Jose\OneDrive - NAIT\BAITS\NETW3100\NETW3100\Lib\site-packages\netmiko\base_connection.py", line 1159, in establish_connection
    raise NetmikoTimeoutException(msg)
netmiko.exceptions.NetmikoTimeoutException: TCP connection to device failed.

Common causes of this problem are:
1. Incorrect hostname or IP address.
2. Wrong TCP port.
3. Intermediate firewall blocking access.

Device settings: cisco_ios 192.168.3.12:22



2023-11-24 10:40:39,393 - nornir.core.task -    ERROR -      start() - Host 'R2': task 'netmiko_send_command' failed with traceback:
Traceback (most recent call last):
  File "C:\Users\Jithin Jose\OneDrive - NAIT\BAITS\NETW3100\NETW3100\Lib\site-packages\netmiko\base_connection.py", line 1137, in establish_connection
    self.remote_conn_pre.connect(**ssh_connect_params)
  File "C:\Users\Jithin Jose\OneDrive - NAIT\BAITS\NETW3100\NETW3100\Lib\site-packages\paramiko\client.py", line 386, in connect
    sock.connect(addr)
TimeoutError: timed out

During handling of the above exception, another exception occurred:

Traceback (most recent call last):
  File "C:\Users\Jithin Jose\OneDrive - NAIT\BAITS\NETW3100\NETW3100\Lib\site-packages\nornir\core\task.py", line 99, in start
    r = self.task(self, **self.params)
        ^^^^^^^^^^^^^^^^^^^^^^^^^^^^^^
  File "C:\Users\Jithin Jose\OneDrive - NAIT\BAITS\NETW3100\NETW3100\Lib\site-packages\nornir_netmiko\tasks\netmiko_send_command.py", line 26, in netmiko_send_command
    net_connect = task.host.get_connection(CONNECTION_NAME, task.nornir.config)
                  ^^^^^^^^^^^^^^^^^^^^^^^^^^^^^^^^^^^^^^^^^^^^^^^^^^^^^^^^^^^^^
  File "C:\Users\Jithin Jose\OneDrive - NAIT\BAITS\NETW3100\NETW3100\Lib\site-packages\nornir\core\inventory.py", line 494, in get_connection
    self.open_connection(
  File "C:\Users\Jithin Jose\OneDrive - NAIT\BAITS\NETW3100\NETW3100\Lib\site-packages\nornir\core\inventory.py", line 546, in open_connection
    conn_obj.open(
  File "C:\Users\Jithin Jose\OneDrive - NAIT\BAITS\NETW3100\NETW3100\Lib\site-packages\nornir_netmiko\connections\netmiko.py", line 59, in open
    connection = ConnectHandler(**parameters)
                 ^^^^^^^^^^^^^^^^^^^^^^^^^^^^
  File "C:\Users\Jithin Jose\OneDrive - NAIT\BAITS\NETW3100\NETW3100\Lib\site-packages\netmiko\ssh_dispatcher.py", line 399, in ConnectHandler
    return ConnectionClass(*args, **kwargs)
           ^^^^^^^^^^^^^^^^^^^^^^^^^^^^^^^^
  File "C:\Users\Jithin Jose\OneDrive - NAIT\BAITS\NETW3100\NETW3100\Lib\site-packages\netmiko\base_connection.py", line 488, in __init__
    self._open()
  File "C:\Users\Jithin Jose\OneDrive - NAIT\BAITS\NETW3100\NETW3100\Lib\site-packages\netmiko\base_connection.py", line 493, in _open
    self.establish_connection()
  File "C:\Users\Jithin Jose\OneDrive - NAIT\BAITS\NETW3100\NETW3100\Lib\site-packages\netmiko\base_connection.py", line 1159, in establish_connection
    raise NetmikoTimeoutException(msg)
netmiko.exceptions.NetmikoTimeoutException: TCP connection to device failed.

Common causes of this problem are:
1. Incorrect hostname or IP address.
2. Wrong TCP port.
3. Intermediate firewall blocking access.

Device settings: cisco_ios 192.168.3.2:22



2023-11-24 10:40:39,393 - nornir.core.task -    ERROR -      start() - Host 'R4': task 'netmiko_send_command' failed with traceback:
Traceback (most recent call last):
  File "C:\Users\Jithin Jose\OneDrive - NAIT\BAITS\NETW3100\NETW3100\Lib\site-packages\netmiko\base_connection.py", line 1137, in establish_connection
    self.remote_conn_pre.connect(**ssh_connect_params)
  File "C:\Users\Jithin Jose\OneDrive - NAIT\BAITS\NETW3100\NETW3100\Lib\site-packages\paramiko\client.py", line 386, in connect
    sock.connect(addr)
TimeoutError: timed out

During handling of the above exception, another exception occurred:

Traceback (most recent call last):
  File "C:\Users\Jithin Jose\OneDrive - NAIT\BAITS\NETW3100\NETW3100\Lib\site-packages\nornir\core\task.py", line 99, in start
    r = self.task(self, **self.params)
        ^^^^^^^^^^^^^^^^^^^^^^^^^^^^^^
  File "C:\Users\Jithin Jose\OneDrive - NAIT\BAITS\NETW3100\NETW3100\Lib\site-packages\nornir_netmiko\tasks\netmiko_send_command.py", line 26, in netmiko_send_command
    net_connect = task.host.get_connection(CONNECTION_NAME, task.nornir.config)
                  ^^^^^^^^^^^^^^^^^^^^^^^^^^^^^^^^^^^^^^^^^^^^^^^^^^^^^^^^^^^^^
  File "C:\Users\Jithin Jose\OneDrive - NAIT\BAITS\NETW3100\NETW3100\Lib\site-packages\nornir\core\inventory.py", line 494, in get_connection
    self.open_connection(
  File "C:\Users\Jithin Jose\OneDrive - NAIT\BAITS\NETW3100\NETW3100\Lib\site-packages\nornir\core\inventory.py", line 546, in open_connection
    conn_obj.open(
  File "C:\Users\Jithin Jose\OneDrive - NAIT\BAITS\NETW3100\NETW3100\Lib\site-packages\nornir_netmiko\connections\netmiko.py", line 59, in open
    connection = ConnectHandler(**parameters)
                 ^^^^^^^^^^^^^^^^^^^^^^^^^^^^
  File "C:\Users\Jithin Jose\OneDrive - NAIT\BAITS\NETW3100\NETW3100\Lib\site-packages\netmiko\ssh_dispatcher.py", line 399, in ConnectHandler
    return ConnectionClass(*args, **kwargs)
           ^^^^^^^^^^^^^^^^^^^^^^^^^^^^^^^^
  File "C:\Users\Jithin Jose\OneDrive - NAIT\BAITS\NETW3100\NETW3100\Lib\site-packages\netmiko\base_connection.py", line 488, in __init__
    self._open()
  File "C:\Users\Jithin Jose\OneDrive - NAIT\BAITS\NETW3100\NETW3100\Lib\site-packages\netmiko\base_connection.py", line 493, in _open
    self.establish_connection()
  File "C:\Users\Jithin Jose\OneDrive - NAIT\BAITS\NETW3100\NETW3100\Lib\site-packages\netmiko\base_connection.py", line 1159, in establish_connection
    raise NetmikoTimeoutException(msg)
netmiko.exceptions.NetmikoTimeoutException: TCP connection to device failed.

Common causes of this problem are:
1. Incorrect hostname or IP address.
2. Wrong TCP port.
3. Intermediate firewall blocking access.

Device settings: cisco_ios 192.168.3.4:22



2023-11-24 10:40:39,393 - nornir.core.task -    ERROR -      start() - Host 'R3': task 'netmiko_send_command' failed with traceback:
Traceback (most recent call last):
  File "C:\Users\Jithin Jose\OneDrive - NAIT\BAITS\NETW3100\NETW3100\Lib\site-packages\netmiko\base_connection.py", line 1137, in establish_connection
    self.remote_conn_pre.connect(**ssh_connect_params)
  File "C:\Users\Jithin Jose\OneDrive - NAIT\BAITS\NETW3100\NETW3100\Lib\site-packages\paramiko\client.py", line 386, in connect
    sock.connect(addr)
TimeoutError: timed out

During handling of the above exception, another exception occurred:

Traceback (most recent call last):
  File "C:\Users\Jithin Jose\OneDrive - NAIT\BAITS\NETW3100\NETW3100\Lib\site-packages\nornir\core\task.py", line 99, in start
    r = self.task(self, **self.params)
        ^^^^^^^^^^^^^^^^^^^^^^^^^^^^^^
  File "C:\Users\Jithin Jose\OneDrive - NAIT\BAITS\NETW3100\NETW3100\Lib\site-packages\nornir_netmiko\tasks\netmiko_send_command.py", line 26, in netmiko_send_command
    net_connect = task.host.get_connection(CONNECTION_NAME, task.nornir.config)
                  ^^^^^^^^^^^^^^^^^^^^^^^^^^^^^^^^^^^^^^^^^^^^^^^^^^^^^^^^^^^^^
  File "C:\Users\Jithin Jose\OneDrive - NAIT\BAITS\NETW3100\NETW3100\Lib\site-packages\nornir\core\inventory.py", line 494, in get_connection
    self.open_connection(
  File "C:\Users\Jithin Jose\OneDrive - NAIT\BAITS\NETW3100\NETW3100\Lib\site-packages\nornir\core\inventory.py", line 546, in open_connection
    conn_obj.open(
  File "C:\Users\Jithin Jose\OneDrive - NAIT\BAITS\NETW3100\NETW3100\Lib\site-packages\nornir_netmiko\connections\netmiko.py", line 59, in open
    connection = ConnectHandler(**parameters)
                 ^^^^^^^^^^^^^^^^^^^^^^^^^^^^
  File "C:\Users\Jithin Jose\OneDrive - NAIT\BAITS\NETW3100\NETW3100\Lib\site-packages\netmiko\ssh_dispatcher.py", line 399, in ConnectHandler
    return ConnectionClass(*args, **kwargs)
           ^^^^^^^^^^^^^^^^^^^^^^^^^^^^^^^^
  File "C:\Users\Jithin Jose\OneDrive - NAIT\BAITS\NETW3100\NETW3100\Lib\site-packages\netmiko\base_connection.py", line 488, in __init__
    self._open()
  File "C:\Users\Jithin Jose\OneDrive - NAIT\BAITS\NETW3100\NETW3100\Lib\site-packages\netmiko\base_connection.py", line 493, in _open
    self.establish_connection()
  File "C:\Users\Jithin Jose\OneDrive - NAIT\BAITS\NETW3100\NETW3100\Lib\site-packages\netmiko\base_connection.py", line 1159, in establish_connection
    raise NetmikoTimeoutException(msg)
netmiko.exceptions.NetmikoTimeoutException: TCP connection to device failed.

Common causes of this problem are:
1. Incorrect hostname or IP address.
2. Wrong TCP port.
3. Intermediate firewall blocking access.

Device settings: cisco_ios 192.168.3.3:22



2023-11-24 10:42:02,354 -  nornir.core -     INFO -        run() - Running task 'netmiko_send_command' with args {'command_string': 'Show ip int br', 'use_textfsm': True} on 10 hosts
2023-11-24 13:17:17,468 -  nornir.core -     INFO -        run() - Running task 'netmiko_send_command' with args {'command_string': 'Show ip int br', 'use_textfsm': True} on 10 hosts
2023-11-24 13:26:21,563 -  nornir.core -     INFO -        run() - Running task 'netmiko_send_command' with args {'command_string': 'Show ip int br', 'use_textfsm': True} on 10 hosts
2023-11-24 13:29:58,739 -  nornir.core -     INFO -        run() - Running task 'netmiko_send_command' with args {'command_string': 'Show ip int br', 'use_textfsm': True} on 10 hosts
